Workbook

Sheet Corpus B
A1: File | B1: Title | C1: Year | D1: Serie | E1: Volume | F1: Language | G1: City | H1: Country | I1: Matches
A2: AMP1834s1v26 | B2: Annales de la médecine physiologique | C2: 1834 | D2: 1 | E2: 26 | F2: French | G2: Paris | H2: France | I2: =_xlfn.LET(_xlpm.id,TRIM($A2),IF(_xlpm.id="","",SUM(COUNTIF('1. OP'!$M:$M,_xlpm.id),COUNTIF('2. JSEL'!$M:$M,_xlpm.id),COUNTIF('3. PSM'!$M:$M,_xlpm.id),COUNTIF('4. SSP'!$M:$M,_xlpm.id),COUNTIF('5. JSACI'!$M:$M,_xlpm.id),COUNTIF('6. AIN'!$M:$M,_xlpm.id),COUNTIF('7. MS'!$M:$M,_xlpm.id),COUNTIF('8. DS'!$M:$M,_xlpm.id),COUNTIF('9. RMF'!$M:$M,_xlpm.id),COUNTIF('10. PCU'!$M:$M,_xlpm.id)))) -> 1
A3: AMP1834s1v25 | B3: Annales de la médecine physiologique | C3: 1834 | D3: 1 | E3: 25 | F3: French | G3: Paris | H3: France | I3: =_xlfn.LET(_xlpm.id,TRIM($A3),IF(_xlpm.id="","",SUM(COUNTIF('1. OP'!$M:$M,_xlpm.id),COUNTIF('2. JSEL'!$M:$M,_xlpm.id),COUNTIF('3. PSM'!$M:$M,_xlpm.id),COUNTIF('4. SSP'!$M:$M,_xlpm.id),COUNTIF('5. JSACI'!$M:$M,_xlpm.id),COUNTIF('6. AIN'!$M:$M,_xlpm.id),COUNTIF('7. MS'!$M:$M,_xlpm.id),COUNTIF('8. DS'!$M:$M,_xlpm.id),COUNTIF('9. RMF'!$M:$M,_xlpm.id),COUNTIF('10. PCU'!$M:$M,_xlpm.id)))) -> 0
A4: AMP1833s1v23 | B4: Annales de la médecine physiologique | C4: 1833 | D4: 1 | E4: 24 | F4: French | G4: Paris | H4: France | I4: =_xlfn.LET(_xlpm.id,TRIM($A4),IF(_xlpm.id="","",SUM(COUNTIF('1. OP'!$M:$M,_xlpm.id),COUNTIF('2. JSEL'!$M:$M,_xlpm.id),COUNTIF('3. PSM'!$M:$M,_xlpm.id),COUNTIF('4. SSP'!$M:$M,_xlpm.id),COUNTIF('5. JSACI'!$M:$M,_xlpm.id),COUNTIF('6. AIN'!$M:$M,_xlpm.id),COUNTIF('7. MS'!$M:$M,_xlpm.id),COUNTIF('8. DS'!$M:$M,_xlpm.id),COUNTIF('9. RMF'!$M:$M,_xlpm.id),COUNTIF('10. PCU'!$M:$M,_xlpm.id)))) -> 0
A5: AMP1833s1v24 | B5: Annales de la médecine physiologique | C5: 1833 | D5: 1 | E5: 23 | F5: French | G5: Paris | H5: France | I5: =_xlfn.LET(_xlpm.id,TRIM($A5),IF(_xlpm.id="","",SUM(COUNTIF('1. OP'!$M:$M,_xlpm.id),COUNTIF('2. JSEL'!$M:$M,_xlpm.id),COUNTIF('3. PSM'!$M:$M,_xlpm.id),COUNTIF('4. SSP'!$M:$M,_xlpm.id),COUNTIF('5. JSACI'!$M:$M,_xlpm.id),COUNTIF('6. AIN'!$M:$M,_xlpm.id),COUNTIF('7. MS'!$M:$M,_xlpm.id),COUNTIF('8. DS'!$M:$M,_xlpm.id),COUNTIF('9. RMF'!$M:$M,_xlpm.id),COUNTIF('10. PCU'!$M:$M,_xlpm.id)))) -> 0
A6: AMP1832s1v22 | B6: Annales de la médecine physiologique | C6: 1832 | D6: 1 | E6: 22 | F6: French | G6: Paris | H6: France | I6: =_xlfn.LET(_xlpm.id,TRIM($A6),IF(_xlpm.id="","",SUM(COUNTIF('1. OP'!$M:$M,_xlpm.id),COUNTIF('2. JSEL'!$M:$M,_xlpm.id),COUNTIF('3. PSM'!$M:$M,_xlpm.id),COUNTIF('4. SSP'!$M:$M,_xlpm.id),COUNTIF('5. JSACI'!$M:$M,_xlpm.id),COUNTIF('6. AIN'!$M:$M,_xlpm.id),COUNTIF('7. MS'!$M:$M,_xlpm.id),COUNTIF('8. DS'!$M:$M,_xlpm.id),COUNTIF('9. RMF'!$M:$M,_xlpm.id),COUNTIF('10. PCU'!$M:$M,_xlpm.id)))) -> 0
A7: AMP1832s1v21 | B7: Annales de la médecine physiologique | C7: 1832 | D7: 1 | E7: 21 | F7: French | G7: Paris | H7: France | I7: =_xlfn.LET(_xlpm.id,TRIM($A7),IF(_xlpm.id="","",SUM(COUNTIF('1. OP'!$M:$M,_xlpm.id),COUNTIF('2. JSEL'!$M:$M,_xlpm.id),COUNTIF('3. PSM'!$M:$M,_xlpm.id),COUNTIF('4. SSP'!$M:$M,_xlpm.id),COUNTIF('5. JSACI'!$M:$M,_xlpm.id),COUNTIF('6. AIN'!$M:$M,_xlpm.id),COUNTIF('7. MS'!$M:$M,_xlpm.id),COUNTIF('8. DS'!$M:$M,_xlpm.id),COUNTIF('9. RMF'!$M:$M,_xlpm.id),COUNTIF('10. PCU'!$M:$M,_xlpm.id)))) -> 0
A8: AMP1831s1v20 | B8: Annales de la médecine physiologique | C8: 1831 | D8: 1 | E8: 20 | F8: French | G8: Paris | H8: France | I8: =_xlfn.LET(_xlpm.id,TRIM($A8),IF(_xlpm.id="","",SUM(COUNTIF('1. OP'!$M:$M,_xlpm.id),COUNTIF('2. JSEL'!$M:$M,_xlpm.id),COUNTIF('3. PSM'!$M:$M,_xlpm.id),COUNTIF('4. SSP'!$M:$M,_xlpm.id),COUNTIF('5. JSACI'!$M:$M,_xlpm.id),COUNTIF('6. AIN'!$M:$M,_xlpm.id),COUNTIF('7. MS'!$M:$M,_xlpm.id),COUNTIF('8. DS'!$M:$M,_xlpm.id),COUNTIF('9. RMF'!$M:$M,_xlpm.id),COUNTIF('10. PCU'!$M:$M,_xlpm.id)))) -> 1
A9: AMP1831s1v19 | B9: Annales de la médecine physiologique | C9: 1831 | D9: 1 | E9: 19 | F9: French | G9: Paris | H9: France | I9: =_xlfn.LET(_xlpm.id,TRIM($A9),IF(_xlpm.id="","",SUM(COUNTIF('1. OP'!$M:$M,_xlpm.id),COUNTIF('2. JSEL'!$M:$M,_xlpm.id),COUNTIF('3. PSM'!$M:$M,_xlpm.id),COUNTIF('4. SSP'!$M:$M,_xlpm.id),COUNTIF('5. JSACI'!$M:$M,_xlpm.id),COUNTIF('6. AIN'!$M:$M,_xlpm.id),COUNTIF('7. MS'!$M:$M,_xlpm.id),COUNTIF('8. DS'!$M:$M,_xlpm.id),COUNTIF('9. RMF'!$M:$M,_xlpm.id),COUNTIF('10. PCU'!$M:$M,_xlpm.id)))) -> 1
A10: AMP1830s1v18 | B10: Annales de la médecine physiologique | C10: 1830 | D10: 1 | E10: 18 | F10: French | G10: Paris | H10: France | I10: =_xlfn.LET(_xlpm.id,TRIM($A10),IF(_xlpm.id="","",SUM(COUNTIF('1. OP'!$M:$M,_xlpm.id),COUNTIF('2. JSEL'!$M:$M,_xlpm.id),COUNTIF('3. PSM'!$M:$M,_xlpm.id),COUNTIF('4. SSP'!$M:$M,_xlpm.id),COUNTIF('5. JSACI'!$M:$M,_xlpm.id),COUNTIF('6. AIN'!$M:$M,_xlpm.id),COUNTIF('7. MS'!$M:$M,_xlpm.id),COUNTIF('8. DS'!$M:$M,_xlpm.id),COUNTIF('9. RMF'!$M:$M,_xlpm.id),COUNTIF('10. PCU'!$M:$M,_xlpm.id)))) -> 0
A11: AMP1830s1v17 | B11: Annales de la médecine physiologique | C11: 1830 | D11: 1 | E11: 17 | F11: French | G11: Paris | H11: France | I11: =_xlfn.LET(_xlpm.id,TRIM($A11),IF(_xlpm.id="","",SUM(COUNTIF('1. OP'!$M:$M,_xlpm.id),COUNTIF('2. JSEL'!$M:$M,_xlpm.id),COUNTIF('3. PSM'!$M:$M,_xlpm.id),COUNTIF('4. SSP'!$M:$M,_xlpm.id),COUNTIF('5. JSACI'!$M:$M,_xlpm.id),COUNTIF('6. AIN'!$M:$M,_xlpm.id),COUNTIF('7. MS'!$M:$M,_xlpm.id),COUNTIF('8. DS'!$M:$M,_xlpm.id),COUNTIF('9. RMF'!$M:$M,_xlpm.id),COUNTIF('10. PCU'!$M:$M,_xlpm.id)))) -> 19
A12: AMP1829s1v16 | B12: Annales de la médecine physiologique | C12: 1829 | D12: 1 | E12: 16 | F12: French | G12: Paris | H12: France | I12: =_xlfn.LET(_xlpm.id,TRIM($A12),IF(_xlpm.id="","",SUM(COUNTIF('1. OP'!$M:$M,_xlpm.id),COUNTIF('2. JSEL'!$M:$M,_xlpm.id),COUNTIF('3. PSM'!$M:$M,_xlpm.id),COUNTIF('4. SSP'!$M:$M,_xlpm.id),COUNTIF('5. JSACI'!$M:$M,_xlpm.id),COUNTIF('6. AIN'!$M:$M,_xlpm.id),COUNTIF('7. MS'!$M:$M,_xlpm.id),COUNTIF('8. DS'!$M:$M,_xlpm.id),COUNTIF('9. RMF'!$M:$M,_xlpm.id),COUNTIF('10. PCU'!$M:$M,_xlpm.id)))) -> 6
A13: AMP1829s1v15 | B13: Annales de la médecine physiologique | C13: 1829 | D13: 1 | E13: 15 | F13: French | G13: Paris | H13: France | I13: =_xlfn.LET(_xlpm.id,TRIM($A13),IF(_xlpm.id="","",SUM(COUNTIF('1. OP'!$M:$M,_xlpm.id),COUNTIF('2. JSEL'!$M:$M,_xlpm.id),COUNTIF('3. PSM'!$M:$M,_xlpm.id),COUNTIF('4. SSP'!$M:$M,_xlpm.id),COUNTIF('5. JSACI'!$M:$M,_xlpm.id),COUNTIF('6. AIN'!$M:$M,_xlpm.id),COUNTIF('7. MS'!$M:$M,_xlpm.id),COUNTIF('8. DS'!$M:$M,_xlpm.id),COUNTIF('9. RMF'!$M:$M,_xlpm.id),COUNTIF('10. PCU'!$M:$M,_xlpm.id)))) -> 0
... A172: JCMP1840s2v6 | B172: Journal de chimie médicale, de pharmacie et de toxicologie | C172: 1840 | D172: 2 | E172: 6 | F172: French | G172: Paris | H172: France | I172: =_xlfn.LET(_xlpm.id,TRIM($A172),IF(_xlpm.id="","",SUM(COUNTIF('1. OP'!$M:$M,_xlpm.id),COUNTIF('2. JSEL'!$M:$M,_xlpm.id),COUNTIF('3. PSM'!$M:$M,_xlpm.id),COUNTIF('4. SSP'!$M:$M,_xlpm.id),COUNTIF('5. JSACI'!$M:$M,_xlpm.id),COUNTIF('6. AIN'!$M:$M,_xlpm.id),COUNTIF('7. MS'!$M:$M,_xlpm.id),COUNTIF('8. DS'!$M:$M,_xlpm.id),COUNTIF('9. RMF'!$M:$M,_xlpm.id),COUNTIF('10. PCU'!$M:$M,_xlpm.id)))) -> 0
A173: JCMC1833-4s1v1 | B173: Journal des Connaissances Medico Chirurgicales | C173: 1833-4 | D173: 1 | E173: 1 | F173: French | G173: Paris | H173: France | I173: =_xlfn.LET(_xlpm.id,TRIM($A173),IF(_xlpm.id="","",SUM(COUNTIF('1. OP'!$M:$M,_xlpm.id),COUNTIF('2. JSEL'!$M:$M,_xlpm.id),COUNTIF('3. PSM'!$M:$M,_xlpm.id),COUNTIF('4. SSP'!$M:$M,_xlpm.id),COUNTIF('5. JSACI'!$M:$M,_xlpm.id),COUNTIF('6. AIN'!$M:$M,_xlpm.id),COUNTIF('7. MS'!$M:$M,_xlpm.id),COUNTIF('8. DS'!$M:$M,_xlpm.id),COUNTIF('9. RMF'!$M:$M,_xlpm.id),COUNTIF('10. PCU'!$M:$M,_xlpm.id)))) -> 20
A174: JCMC1834-5s1v2 | B174: Journal des Connaissances Medico Chirurgicales | C174: 1834-5 | D174: 1 | E174: 2 | F174: French | G174: Paris | H174: France | I174: =_xlfn.LET(_xlpm.id,TRIM($A174),IF(_xlpm.id="","",SUM(COUNTIF('1. OP'!$M:$M,_xlpm.id),COUNTIF('2. JSEL'!$M:$M,_xlpm.id),COUNTIF('3. PSM'!$M:$M,_xlpm.id),COUNTIF('4. SSP'!$M:$M,_xlpm.id),COUNTIF('5. JSACI'!$M:$M,_xlpm.id),COUNTIF('6. AIN'!$M:$M,_xlpm.id),COUNTIF('7. MS'!$M:$M,_xlpm.id),COUNTIF('8. DS'!$M:$M,_xlpm.id),COUNTIF('9. RMF'!$M:$M,_xlpm.id),COUNTIF('10. PCU'!$M:$M,_xlpm.id)))) -> 12
A175: JCMC1835-6s1v3 | B175: Journal des Connaissances Medico Chirurgicales | C175: 1835-6 | D175: 1 | E175: 3 | F175: French | G175: Paris | H175: France | I175: =_xlfn.LET(_xlpm.id,TRIM($A175),IF(_xlpm.id="","",SUM(COUNTIF('1. OP'!$M:$M,_xlpm.id),COUNTIF('2. JSEL'!$M:$M,_xlpm.id),COUNTIF('3. PSM'!$M:$M,_xlpm.id),COUNTIF('4. SSP'!$M:$M,_xlpm.id),COUNTIF('5. JSACI'!$M:$M,_xlpm.id),COUNTIF('6. AIN'!$M:$M,_xlpm.id),COUNTIF('7. MS'!$M:$M,_xlpm.id),COUNTIF('8. DS'!$M:$M,_xlpm.id),COUNTIF('9. RMF'!$M:$M,_xlpm.id),COUNTIF('10. PCU'!$M:$M,_xlpm.id)))) -> 0
A176: JCMC1836-7s1v4 | B176: Journal des Connaissances Medico Chirurgicales | C176: 1836-7 | D176: 1 | E176: 4 | F176: French | G176: Paris | H176: France | I176: =_xlfn.LET(_xlpm.id,TRIM($A176),IF(_xlpm.id="","",SUM(COUNTIF('1. OP'!$M:$M,_xlpm.id),COUNTIF('2. JSEL'!$M:$M,_xlpm.id),COUNTIF('3. PSM'!$M:$M,_xlpm.id),COUNTIF('4. SSP'!$M:$M,_xlpm.id),COUNTIF('5. JSACI'!$M:$M,_xlpm.id),COUNTIF('6. AIN'!$M:$M,_xlpm.id),COUNTIF('7. MS'!$M:$M,_xlpm.id),COUNTIF('8. DS'!$M:$M,_xlpm.id),COUNTIF('9. RMF'!$M:$M,_xlpm.id),COUNTIF('10. PCU'!$M:$M,_xlpm.id)))) -> 5
A177: JCMC1837-8s1v5 | B177: Journal des Connaissances Medico Chirurgicales | C177: 1837-8 | D177: 1 | E177: 5 | F177: French | G177: Paris | H177: France | I177: =_xlfn.LET(_xlpm.id,TRIM($A177),IF(_xlpm.id="","",SUM(COUNTIF('1. OP'!$M:$M,_xlpm.id),COUNTIF('2. JSEL'!$M:$M,_xlpm.id),COUNTIF('3. PSM'!$M:$M,_xlpm.id),COUNTIF('4. SSP'!$M:$M,_xlpm.id),COUNTIF('5. JSACI'!$M:$M,_xlpm.id),COUNTIF('6. AIN'!$M:$M,_xlpm.id),COUNTIF('7. MS'!$M:$M,_xlpm.id),COUNTIF('8. DS'!$M:$M,_xlpm.id),COUNTIF('9. RMF'!$M:$M,_xlpm.id),COUNTIF('10. PCU'!$M:$M,_xlpm.id)))) -> 7
A178: JCMC1838-9s1v6 | B178: Journal des Connaissances Medico Chirurgicales | C178: 1838-9 | D178: 1 | E178: 6 | F178: French | G178: Paris | H178: France | I178: =_xlfn.LET(_xlpm.id,TRIM($A178),IF(_xlpm.id="","",SUM(COUNTIF('1. OP'!$M:$M,_xlpm.id),COUNTIF('2. JSEL'!$M:$M,_xlpm.id),COUNTIF('3. PSM'!$M:$M,_xlpm.id),COUNTIF('4. SSP'!$M:$M,_xlpm.id),COUNTIF('5. JSACI'!$M:$M,_xlpm.id),COUNTIF('6. AIN'!$M:$M,_xlpm.id),COUNTIF('7. MS'!$M:$M,_xlpm.id),COUNTIF('8. DS'!$M:$M,_xlpm.id),COUNTIF('9. RMF'!$M:$M,_xlpm.id),COUNTIF('10. PCU'!$M:$M,_xlpm.id)))) -> 17
A179: JCMC1839s1v7 | B179: Journal des Connaissances Medico Chirurgicales | C179: 1839 | D179: 1 | E179: 7 | F179: French | G179: Paris | H179: France | I179: =_xlfn.LET(_xlpm.id,TRIM($A179),IF(_xlpm.id="","",SUM(COUNTIF('1. OP'!$M:$M,_xlpm.id),COUNTIF('2. JSEL'!$M:$M,_xlpm.id),COUNTIF('3. PSM'!$M:$M,_xlpm.id),COUNTIF('4. SSP'!$M:$M,_xlpm.id),COUNTIF('5. JSACI'!$M:$M,_xlpm.id),COUNTIF('6. AIN'!$M:$M,_xlpm.id),COUNTIF('7. MS'!$M:$M,_xlpm.id),COUNTIF('8. DS'!$M:$M,_xlpm.id),COUNTIF('9. RMF'!$M:$M,_xlpm.id),COUNTIF('10. PCU'!$M:$M,_xlpm.id)))) -> 7
A180: JCMC1840s1v8 | B180: Journal des Connaissances Medico Chirurgicales | C180: 1840 | D180: 1 | E180: 8 | F180: French | G180: Paris | H180: France | I180: =_xlfn.LET(_xlpm.id,TRIM($A180),IF(_xlpm.id="","",SUM(COUNTIF('1. OP'!$M:$M,_xlpm.id),COUNTIF('2. JSEL'!$M:$M,_xlpm.id),COUNTIF('3. PSM'!$M:$M,_xlpm.id),COUNTIF('4. SSP'!$M:$M,_xlpm.id),COUNTIF('5. JSACI'!$M:$M,_xlpm.id),COUNTIF('6. AIN'!$M:$M,_xlpm.id),COUNTIF('7. MS'!$M:$M,_xlpm.id),COUNTIF('8. DS'!$M:$M,_xlpm.id),COUNTIF('9. RMF'!$M:$M,_xlpm.id),COUNTIF('10. PCU'!$M:$M,_xlpm.id)))) -> 0
A181: JPSA1815s1v1 | B181: Journal de pharmacie et des sciences accessoires | C181: 1815 | D181: 1 | E181: 1 | F181: French | G181: Paris | H181: France | I181: =_xlfn.LET(_xlpm.id,TRIM($A181),IF(_xlpm.id="","",SUM(COUNTIF('1. OP'!$M:$M,_xlpm.id),COUNTIF('2. JSEL'!$M:$M,_xlpm.id),COUNTIF('3. PSM'!$M:$M,_xlpm.id),COUNTIF('4. SSP'!$M:$M,_xlpm.id),COUNTIF('5. JSACI'!$M:$M,_xlpm.id),COUNTIF('6. AIN'!$M:$M,_xlpm.id),COUNTIF('7. MS'!$M:$M,_xlpm.id),COUNTIF('8. DS'!$M:$M,_xlpm.id),COUNTIF('9. RMF'!$M:$M,_xlpm.id),COUNTIF('10. PCU'!$M:$M,_xlpm.id)))) -> 0
A182: JPSA1816s1v2 | B182: Journal de pharmacie et des sciences accessoires | C182: 1816 | D182: 1 | E182: 2 | F182: French | G182: Paris | H182: France | I182: =_xlfn.LET(_xlpm.id,TRIM($A182),IF(_xlpm.id="","",SUM(COUNTIF('1. OP'!$M:$M,_xlpm.id),COUNTIF('2. JSEL'!$M:$M,_xlpm.id),COUNTIF('3. PSM'!$M:$M,_xlpm.id),COUNTIF('4. SSP'!$M:$M,_xlpm.id),COUNTIF('5. JSACI'!$M:$M,_xlpm.id),COUNTIF('6. AIN'!$M:$M,_xlpm.id),COUNTIF('7. MS'!$M:$M,_xlpm.id),COUNTIF('8. DS'!$M:$M,_xlpm.id),COUNTIF('9. RMF'!$M:$M,_xlpm.id),COUNTIF('10. PCU'!$M:$M,_xlpm.id)))) -> 0
A183: JPSA1817s1v3 | B183: Journal de pharmacie et des sciences accessoires | C183: 1817 | D183: 1 | E183: 3 | F183: French | G183: Paris | H183: France | I183: =_xlfn.LET(_xlpm.id,TRIM($A183),IF(_xlpm.id="","",SUM(COUNTIF('1. OP'!$M:$M,_xlpm.id),COUNTIF('2. JSEL'!$M:$M,_xlpm.id),COUNTIF('3. PSM'!$M:$M,_xlpm.id),COUNTIF('4. SSP'!$M:$M,_xlpm.id),COUNTIF('5. JSACI'!$M:$M,_xlpm.id),COUNTIF('6. AIN'!$M:$M,_xlpm.id),COUNTIF('7. MS'!$M:$M,_xlpm.id),COUNTIF('8. DS'!$M:$M,_xlpm.id),COUNTIF('9. RMF'!$M:$M,_xlpm.id),COUNTIF('10. PCU'!$M:$M,_xlpm.id)))) -> 0
A184: JPSA1818s1v4 | B184: Journal de pharmacie et des sciences accessoires | C184: 1818 | D184: 1 | E184: 4 | F184: French | G184: Paris | H184: France | I184: =_xlfn.LET(_xlpm.id,TRIM($A184),IF(_xlpm.id="","",SUM(COUNTIF('1. OP'!$M:$M,_xlpm.id),COUNTIF('2. JSEL'!$M:$M,_xlpm.id),COUNTIF('3. PSM'!$M:$M,_xlpm.id),COUNTIF('4. SSP'!$M:$M,_xlpm.id),COUNTIF('5. JSACI'!$M:$M,_xlpm.id),COUNTIF('6. AIN'!$M:$M,_xlpm.id),COUNTIF('7. MS'!$M:$M,_xlpm.id),COUNTIF('8. DS'!$M:$M,_xlpm.id),COUNTIF('9. RMF'!$M:$M,_xlpm.id),COUNTIF('10. PCU'!$M:$M,_xlpm.id)))) -> 0
A185: JPSA1819s1v5 | B185: Journal de pharmacie et des sciences accessoires | C185: 1819 | D185: 1 | E185: 5 | F185: French | G185: Paris | H185: France | I185: =_xlfn.LET(_xlpm.id,TRIM($A185),IF(_xlpm.id="","",SUM(COUNTIF('1. OP'!$M:$M,_xlpm.id),COUNTIF('2. JSEL'!$M:$M,_xlpm.id),COUNTIF('3. PSM'!$M:$M,_xlpm.id),COUNTIF('4. SSP'!$M:$M,_xlpm.id),COUNTIF('5. JSACI'!$M:$M,_xlpm.id),COUNTIF('6. AIN'!$M:$M,_xlpm.id),COUNTIF('7. MS'!$M:$M,_xlpm.id),COUNTIF('8. DS'!$M:$M,_xlpm.id),COUNTIF('9. RMF'!$M:$M,_xlpm.id),COUNTIF('10. PCU'!$M:$M,_xlpm.id)))) -> 0
A186: JPSA1820s1v6 | B186: Journal de pharmacie et des sciences accessoires | C186: 1820 | D186: 1 | E186: 6 | F186: French | G186: Paris | H186: France | I186: =_xlfn.LET(_xlpm.id,TRIM($A186),IF(_xlpm.id="","",SUM(COUNTIF('1. OP'!$M:$M,_xlpm.id),COUNTIF('2. JSEL'!$M:$M,_xlpm.id),COUNTIF('3. PSM'!$M:$M,_xlpm.id),COUNTIF('4. SSP'!$M:$M,_xlpm.id),COUNTIF('5. JSACI'!$M:$M,_xlpm.id),COUNTIF('6. AIN'!$M:$M,_xlpm.id),COUNTIF('7. MS'!$M:$M,_xlpm.id),COUNTIF('8. DS'!$M:$M,_xlpm.id),COUNTIF('9. RMF'!$M:$M,_xlpm.id),COUNTIF('10. PCU'!$M:$M,_xlpm.id)))) -> 0
A187: JPSA1821s1v7 | B187: Journal de pharmacie et des sciences accessoires | C187: 1821 | D187: 1 | E187: 7 | F187: French | G187: Paris | H187: France | I187: =_xlfn.LET(_xlpm.id,TRIM($A187),IF(_xlpm.id="","",SUM(COUNTIF('1. OP'!$M:$M,_xlpm.id),COUNTIF('2. JSEL'!$M:$M,_xlpm.id),COUNTIF('3. PSM'!$M:$M,_xlpm.id),COUNTIF('4. SSP'!$M:$M,_xlpm.id),COUNTIF('5. JSACI'!$M:$M,_xlpm.id),COUNTIF('6. AIN'!$M:$M,_xlpm.id),COUNTIF('7. MS'!$M:$M,_xlpm.id),COUNTIF('8. DS'!$M:$M,_xlpm.id),COUNTIF('9. RMF'!$M:$M,_xlpm.id),COUNTIF('10. PCU'!$M:$M,_xlpm.id)))) -> 0
A188: JPSA1822s1v8 | B188: Journal de pharmacie et des sciences accessoires | C188: 1822 | D188: 1 | E188: 8 | F188: French | G188: Paris | H188: France | I188: =_xlfn.LET(_xlpm.id,TRIM($A188),IF(_xlpm.id="","",SUM(COUNTIF('1. OP'!$M:$M,_xlpm.id),COUNTIF('2. JSEL'!$M:$M,_xlpm.id),COUNTIF('3. PSM'!$M:$M,_xlpm.id),COUNTIF('4. SSP'!$M:$M,_xlpm.id),COUNTIF('5. JSACI'!$M:$M,_xlpm.id),COUNTIF('6. AIN'!$M:$M,_xlpm.id),COUNTIF('7. MS'!$M:$M,_xlpm.id),COUNTIF('8. DS'!$M:$M,_xlpm.id),COUNTIF('9. RMF'!$M:$M,_xlpm.id),COUNTIF('10. PCU'!$M:$M,_xlpm.id)))) -> 0
A189: JPSA1823s1v9 | B189: Journal de pharmacie et des sciences accessoires | C189: 1823 | D189: 1 | E189: 9 | F189: French | G189: Paris | H189: France | I189: =_xlfn.LET(_xlpm.id,TRIM($A189),IF(_xlpm.id="","",SUM(COUNTIF('1. OP'!$M:$M,_xlpm.id),COUNTIF('2. JSEL'!$M:$M,_xlpm.id),COUNTIF('3. PSM'!$M:$M,_xlpm.id),COUNTIF('4. SSP'!$M:$M,_xlpm.id),COUNTIF('5. JSACI'!$M:$M,_xlpm.id),COUNTIF('6. AIN'!$M:$M,_xlpm.id),COUNTIF('7. MS'!$M:$M,_xlpm.id),COUNTIF('8. DS'!$M:$M,_xlpm.id),COUNTIF('9. RMF'!$M:$M,_xlpm.id),COUNTIF('10. PCU'!$M:$M,_xlpm.id)))) -> 2
A190: JPSA1824s1v10 | B190: Journal de pharmacie et des sciences accessoires | C190: 1824 | D190: 1 | E190: 10 | F190: French | G190: Paris | H190: France | I190: =_xlfn.LET(_xlpm.id,TRIM($A190),IF(_xlpm.id="","",SUM(COUNTIF('1. OP'!$M:$M,_xlpm.id),COUNTIF('2. JSEL'!$M:$M,_xlpm.id),COUNTIF('3. PSM'!$M:$M,_xlpm.id),COUNTIF('4. SSP'!$M:$M,_xlpm.id),COUNTIF('5. JSACI'!$M:$M,_xlpm.id),COUNTIF('6. AIN'!$M:$M,_xlpm.id),COUNTIF('7. MS'!$M:$M,_xlpm.id),COUNTIF('8. DS'!$M:$M,_xlpm.id),COUNTIF('9. RMF'!$M:$M,_xlpm.id),COUNTIF('10. PCU'!$M:$M,_xlpm.id)))) -> 5
... A209: MF1836s1v3 | B209: Musée des familles | C209: 1836 | D209: 1 | E209: 3 | F209: French | G209: Paris | H209: France | I209: =_xlfn.LET(_xlpm.id,TRIM($A209),IF(_xlpm.id="","",SUM(COUNTIF('1. OP'!$M:$M,_xlpm.id),COUNTIF('2. JSEL'!$M:$M,_xlpm.id),COUNTIF('3. PSM'!$M:$M,_xlpm.id),COUNTIF('4. SSP'!$M:$M,_xlpm.id),COUNTIF('5. JSACI'!$M:$M,_xlpm.id),COUNTIF('6. AIN'!$M:$M,_xlpm.id),COUNTIF('7. MS'!$M:$M,_xlpm.id),COUNTIF('8. DS'!$M:$M,_xlpm.id),COUNTIF('9. RMF'!$M:$M,_xlpm.id),COUNTIF('10. PCU'!$M:$M,_xlpm.id)))) -> 0
A210: MF1836-1837s1v4 | B210: Musée des familles | C210: 1836-1837 | D210: 1 | E210: 4 | F210: French | G210: Paris | H210: France | I210: =_xlfn.LET(_xlpm.id,TRIM($A210),IF(_xlpm.id="","",SUM(COUNTIF('1. OP'!$M:$M,_xlpm.id),COUNTIF('2. JSEL'!$M:$M,_xlpm.id),COUNTIF('3. PSM'!$M:$M,_xlpm.id),COUNTIF('4. SSP'!$M:$M,_xlpm.id),COUNTIF('5. JSACI'!$M:$M,_xlpm.id),COUNTIF('6. AIN'!$M:$M,_xlpm.id),COUNTIF('7. MS'!$M:$M,_xlpm.id),COUNTIF('8. DS'!$M:$M,_xlpm.id),COUNTIF('9. RMF'!$M:$M,_xlpm.id),COUNTIF('10. PCU'!$M:$M,_xlpm.id)))) -> 0
A211: MF1837-1838s1v5 | B211: Musée des familles | C211: 1837-1838 | D211: 1 | E211: 5 | F211: French | G211: Paris | H211: France | I211: =_xlfn.LET(_xlpm.id,TRIM($A211),IF(_xlpm.id="","",SUM(COUNTIF('1. OP'!$M:$M,_xlpm.id),COUNTIF('2. JSEL'!$M:$M,_xlpm.id),COUNTIF('3. PSM'!$M:$M,_xlpm.id),COUNTIF('4. SSP'!$M:$M,_xlpm.id),COUNTIF('5. JSACI'!$M:$M,_xlpm.id),COUNTIF('6. AIN'!$M:$M,_xlpm.id),COUNTIF('7. MS'!$M:$M,_xlpm.id),COUNTIF('8. DS'!$M:$M,_xlpm.id),COUNTIF('9. RMF'!$M:$M,_xlpm.id),COUNTIF('10. PCU'!$M:$M,_xlpm.id)))) -> 0
A212: LMU1833-1834s1v1 | B212: Le Magasin Universel | C212: 1833-1834 | D212: 1 | E212: 1 | F212: French | G212: Paris | H212: France | I212: =_xlfn.LET(_xlpm.id,TRIM($A212),IF(_xlpm.id="","",SUM(COUNTIF('1. OP'!$M:$M,_xlpm.id),COUNTIF('2. JSEL'!$M:$M,_xlpm.id),COUNTIF('3. PSM'!$M:$M,_xlpm.id),COUNTIF('4. SSP'!$M:$M,_xlpm.id),COUNTIF('5. JSACI'!$M:$M,_xlpm.id),COUNTIF('6. AIN'!$M:$M,_xlpm.id),COUNTIF('7. MS'!$M:$M,_xlpm.id),COUNTIF('8. DS'!$M:$M,_xlpm.id),COUNTIF('9. RMF'!$M:$M,_xlpm.id),COUNTIF('10. PCU'!$M:$M,_xlpm.id)))) -> 2
A213: LMU1834-1835s1v2 | B213: Le Magasin Universel | C213: 1834-1835 | D213: 1 | E213: 2 | F213: French | G213: Paris | H213: France | I213: =_xlfn.LET(_xlpm.id,TRIM($A213),IF(_xlpm.id="","",SUM(COUNTIF('1. OP'!$M:$M,_xlpm.id),COUNTIF('2. JSEL'!$M:$M,_xlpm.id),COUNTIF('3. PSM'!$M:$M,_xlpm.id),COUNTIF('4. SSP'!$M:$M,_xlpm.id),COUNTIF('5. JSACI'!$M:$M,_xlpm.id),COUNTIF('6. AIN'!$M:$M,_xlpm.id),COUNTIF('7. MS'!$M:$M,_xlpm.id),COUNTIF('8. DS'!$M:$M,_xlpm.id),COUNTIF('9. RMF'!$M:$M,_xlpm.id),COUNTIF('10. PCU'!$M:$M,_xlpm.id)))) -> 0
A214: LMU1835-1836s1v3 | B214: Le Magasin Universel | C214: 1835-1836 | D214: 1 | E214: 3 | F214: French | G214: Paris | H214: France | I214: =_xlfn.LET(_xlpm.id,TRIM($A214),IF(_xlpm.id="","",SUM(COUNTIF('1. OP'!$M:$M,_xlpm.id),COUNTIF('2. JSEL'!$M:$M,_xlpm.id),COUNTIF('3. PSM'!$M:$M,_xlpm.id),COUNTIF('4. SSP'!$M:$M,_xlpm.id),COUNTIF('5. JSACI'!$M:$M,_xlpm.id),COUNTIF('6. AIN'!$M:$M,_xlpm.id),COUNTIF('7. MS'!$M:$M,_xlpm.id),COUNTIF('8. DS'!$M:$M,_xlpm.id),COUNTIF('9. RMF'!$M:$M,_xlpm.id),COUNTIF('10. PCU'!$M:$M,_xlpm.id)))) -> 1
A215: LMU1836-1837s1v4 | B215: Le Magasin Universel | C215: 1836-1837 | D215: 1 | E215: 4 | F215: French | G215: Paris | H215: France | I215: =_xlfn.LET(_xlpm.id,TRIM($A215),IF(_xlpm.id="","",SUM(COUNTIF('1. OP'!$M:$M,_xlpm.id),COUNTIF('2. JSEL'!$M:$M,_xlpm.id),COUNTIF('3. PSM'!$M:$M,_xlpm.id),COUNTIF('4. SSP'!$M:$M,_xlpm.id),COUNTIF('5. JSACI'!$M:$M,_xlpm.id),COUNTIF('6. AIN'!$M:$M,_xlpm.id),COUNTIF('7. MS'!$M:$M,_xlpm.id),COUNTIF('8. DS'!$M:$M,_xlpm.id),COUNTIF('9. RMF'!$M:$M,_xlpm.id),COUNTIF('10. PCU'!$M:$M,_xlpm.id)))) -> 0
A216: LMU1837-1838s1v5 | B216: Le Magasin Universel | C216: 1837-1838 | D216: 1 | E216: 5 | F216: French | G216: Paris | H216: France | I216: =_xlfn.LET(_xlpm.id,TRIM($A216),IF(_xlpm.id="","",SUM(COUNTIF('1. OP'!$M:$M,_xlpm.id),COUNTIF('2. JSEL'!$M:$M,_xlpm.id),COUNTIF('3. PSM'!$M:$M,_xlpm.id),COUNTIF('4. SSP'!$M:$M,_xlpm.id),COUNTIF('5. JSACI'!$M:$M,_xlpm.id),COUNTIF('6. AIN'!$M:$M,_xlpm.id),COUNTIF('7. MS'!$M:$M,_xlpm.id),COUNTIF('8. DS'!$M:$M,_xlpm.id),COUNTIF('9. RMF'!$M:$M,_xlpm.id),COUNTIF('10. PCU'!$M:$M,_xlpm.id)))) -> 0
...

Sheet Corpus A
A1: File | B1: Full title | C1: Short title | D1: Initialism | E1: Start | F1: End | G1: Serie | H1: Volume | I1: Language
A2: OP1813s1v1 | B2: O Patriota: jornal litterario, politico, mercantil, do Rio de Janeiro | C2: O Patriota | D2: OP | E2: 1813 | F2: 1813 | G2: 1 | H2: 1 | I2: Portuguese
A3: OP1813s1v2 | B3: O Patriota: jornal litterario, politico, mercantil, do Rio de Janeiro | C3: O Patriota | D3: OP | E3: 1813 | F3: 1813 | G3: 1 | H3: 2 | I3: Portuguese
A4: OP1814s1v3 | B4: O Patriota: jornal litterario, politico, mercantil, do Rio de Janeiro | C4: O Patriota | D4: OP | E4: 1814 | F4: 1814 | G4: 1 | H4: 3 | I4: Portuguese
A5: JSEL1826s1v1n1 | B5: Jornal Scientifico, Economico e Litterario, ou Collecao de varias pecas, memorias, relacoens, viagens, poesias e anedoctas. Mixto de instruccao e de recreio, accommodado a todo o genero de leitores. | C5: Jornal Scientifico, Economico e Litterario | D5: JSEL | E5: 1826 | F5: 1826 | G5: 1 | H5: 1 | I5: Portuguese
A6: JSEL1826s1v1n2 | B6: Jornal Scientifico, Economico e Litterario, ou Collecao de varias pecas, memorias, relacoens, viagens, poesias e anedoctas. Mixto de instruccao e de recreio, accommodado a todo o genero de leitores. | C6: Jornal Scientifico, Economico e Litterario | D6: JSEL | E6: 1826 | F6: 1826 | G6: 1 | H6: 1 | I6: Portuguese
A7: JSEL1826s1v1n3 | B7: Jornal Scientifico, Economico e Litterario, ou Collecao de varias pecas, memorias, relacoens, viagens, poesias e anedoctas. Mixto de instruccao e de recreio, accommodado a todo o genero de leitores. | C7: Jornal Scientifico, Economico e Litterario | D7: JSEL | E7: 1826 | F7: 1826 | G7: 1 | H7: 1 | I7: Portuguese
A8: PSM1827s1v1 | B8: O Propagador das Sciencias Medicas, ou Annaes de Medicina, Cirurgia, e Pharmacia; para o Imperio do Brasil e naçoes estrangeiras, seguidos de hum boletim especialmente consagrado as sciencias naturaes, zoologia, botanica. | C8: O Propagador das Sciencias Medicas | D8: PSM | E8: 1827 | F8: 1827 | G8: 1 | H8: 1 | I8: Portuguese
A9: PSM1827s1v2 | B9: O Propagador das Sciencias Medicas, ou Annaes de Medicina, Cirurgia, e Pharmacia; para o Imperio do Brasil e naçoes estrangeiras, seguidos de hum boletim especialmente consagrado as sciencias naturaes, zoologia, botanica. | C9: O Propagador das Sciencias Medicas | D9: PSM | E9: 1827 | F9: 1827 | G9: 1 | H9: 2 | I9: Portuguese
A10: PSM1827s1v3 | B10: O Propagador das Sciencias Medicas, ou Annaes de Medicina, Cirurgia, e Pharmacia; para o Imperio do Brasil e naçoes estrangeiras, seguidos de hum boletim especialmente consagrado as sciencias naturaes, zoologia, botanica. | C10: O Propagador das Sciencias Medicas | D10: PSM | E10: 1827 | F10: 1827 | G10: 1 | H10: 3 | I10: Portuguese
A11: PSM1827-8s1v4 | B11: O Propagador das Sciencias Medicas, ou Annaes de Medicina, Cirurgia, e Pharmacia; para o Imperio do Brasil e naçoes estrangeiras, seguidos de hum boletim especialmente consagrado as sciencias naturaes, zoologia, botanica. | C11: O Propagador das Sciencias Medicas | D11: PSM | E11: 1827 | F11: 1828 | G11: 1 | H11: 4 | I11: Portuguese
A12: SSP1831s1v1n1-53 | B12: Semanario de Saude Publica: pela Sociedade de Medicina do Rio de Janeiro. | C12: Semanario de Saude Publica | D12: SSP | E12: 1831 | F12: 1831 | G12: 1 | H12: 1 | I12: Portuguese
A13: SSP1832s1v1n54-132 | B13: Semanario de Saude Publica: pela Sociedade de Medicina do Rio de Janeiro. | C13: Semanario de Saude Publica | D13: SSP | E13: 1832 | F13: 1832 | G13: 1 | H13: 1 | I13: Portuguese
... A35: PCU1836s1v1n8 | B35: O Propagador de Conhecimentos Uteis | C35: O Propagador de Conhecimentos Uteis | D35: PCU | E35: 1836 | F35: 1836 | G35: 1 | H35: 1 | I35: Portuguese

Sheet Overview
C1: 1. OP | D1: 2. JSEL | E1: 3. PSM | F1: 4. SSP | G1: 5. JSACI | H1: 6. AIN | I1: 7. MS | J1: 8. DS | K1: 9. RMF | L1: 10. PCU
A2: Size | B2: Total, Articles | C2: =COUNTA('1. OP'!J2:J1048576) -> 289 | D2: =COUNTA('2. JSEL'!J2:J1048576) -> 47 | E2: =COUNTA('3. PSM'!J2:J1048576) -> 205 | F2: =COUNTA('4. SSP'!J2:J1048576) -> 494 | G2: =COUNTA('5. JSACI'!J2:J1048576) -> 45 | H2: =COUNTA('6. AIN'!J2:J1048576) -> 857 | I2: =COUNTA('7. MS'!J2:J1048576) -> 16 | J2: =COUNTA('8. DS'!J2:J1048576) -> 384 | K2: =COUNTA('9. RMF'!J2:J1048576) -> 703 | L2: =COUNTA('10. PCU'!J2:J1048576) -> 8
B3: Total, Pages | C3: =SUM('1. OP'!H2:H5536) -> 1849 | D3: =SUM('2. JSEL'!H2:H1048576) -> 279 | E3: =SUM('3. PSM'!H2:H1048576) -> 1063 | F3: =SUM('4. SSP'!H2:H1048576) -> 563 | G3: =SUM('5. JSACI'!H2:H1048576) -> 235 | H3: =SUM('6. AIN'!H2:H1048576) -> 3323 | I3: =SUM('7. MS'!H2:H1048573) -> 14 | J3: =SUM('8. DS'!H2:H1048576) -> 427 | K3: =SUM('9. RMF'!H2:H1048576) -> 2886 | L3: =SUM('10. PCU'!H2:H1048576) -> 16
A4: Scientific | B4: Yes (Articles) | C4: {=SUM(_xlfn.BYROW('1. OP'!R2:R10002, _xlfn.LAMBDA(_xlpm.x, --ISNUMBER(MATCH("TRUE", _xlfn.TEXTSPLIT(LOWER(_xlpm.x)," "), 0)))))} -> 67 | D4: {=SUM(_xlfn.BYROW('2. JSEL'!R2:R48, _xlfn.LAMBDA(_xlpm.x, --ISNUMBER(MATCH("TRUE", _xlfn.TEXTSPLIT(LOWER(_xlpm.x)," "), 0)))))} -> 15 | E4: {=SUM(_xlfn.BYROW('3. PSM'!R2:R206, _xlfn.LAMBDA(_xlpm.x, --ISNUMBER(MATCH("TRUE", _xlfn.TEXTSPLIT(LOWER(_xlpm.x)," "), 0)))))} -> 205 | F4: {=SUM(_xlfn.BYROW('4. SSP'!R2:R495, _xlfn.LAMBDA(_xlpm.x, --ISNUMBER(MATCH("TRUE", _xlfn.TEXTSPLIT(LOWER(_xlpm.x)," "), 0)))))} -> 418 | G4: {=SUM(_xlfn.BYROW('5. JSACI'!R2:R46, _xlfn.LAMBDA(_xlpm.x, --ISNUMBER(MATCH("TRUE", _xlfn.TEXTSPLIT(LOWER(_xlpm.x)," "), 0)))))} -> 28 | H4: {=SUM(_xlfn.BYROW('6. AIN'!R2:R858, _xlfn.LAMBDA(_xlpm.x, --ISNUMBER(MATCH("TRUE", _xlfn.TEXTSPLIT(LOWER(_xlpm.x)," "), 0)))))} -> 722 | I4: {=SUM(_xlfn.BYROW('7. MS'!R2:R9999, _xlfn.LAMBDA(_xlpm.x, --ISNUMBER(MATCH("TRUE", _xlfn.TEXTSPLIT(LOWER(_xlpm.x)," "), 0)))))} -> 13 | J4: {=SUM(_xlfn.BYROW('8. DS'!R2:R10006, _xlfn.LAMBDA(_xlpm.x, --ISNUMBER(MATCH("TRUE", _xlfn.TEXTSPLIT(LOWER(_xlpm.x)," "), 0)))))} -> 382 | K4: {=SUM(_xlfn.BYROW('9. RMF'!R2:R10124, _xlfn.LAMBDA(_xlpm.x, --ISNUMBER(MATCH("TRUE", _xlfn.TEXTSPLIT(LOWER(_xlpm.x)," "), 0)))))} -> 557 | L4: {=SUM(_xlfn.BYROW('10. PCU'!R2:R10001, _xlfn.LAMBDA(_xlpm.x, --ISNUMBER(MATCH("TRUE", _xlfn.TEXTSPLIT(LOWER(_xlpm.x)," "), 0)))))} -> 4
B5: Yes (Pages) | C5: =SUMIF('1. OP'!$R:$R,"TRUE",'1. OP'!$H:$H) -> 741.5 | D5: =SUMIF('2. JSEL'!$R:$R,"TRUE",'2. JSEL'!$H:$H) -> 132.5 | E5: =SUMIF('3. PSM'!$R:$R,"TRUE",'3. PSM'!$H:$H) -> 1063 | F5: =SUMIF('4. SSP'!$R:$R,"TRUE",'4. SSP'!$H:$H) -> 477.88333 | G5: =SUMIF('5. JSACI'!$R:$R,"TRUE",'5. JSACI'!$H:$H) -> 162.33333 | H5: =SUMIF('6. AIN'!$R:$R,"TRUE",'6. AIN'!$H:$H) -> 3005.8333 | I5: =SUMIF('7. MS'!$R:$R,"TRUE",'7. MS'!$H:$H) -> 12 | J5: =SUMIF('8. DS'!$R:$R,"TRUE",'8. DS'!$H:$H) -> 426.05 | K5: =SUMIF('9. RMF'!$R:$R,"TRUE",'9. RMF'!$H:$H) -> 2492.1667 | L5: =SUMIF('10. PCU'!$R:$R,"TRUE",'10. PCU'!$H:$H) -> 6.25
B6: Science-Ratio (Articles) | C6: =IFERROR(C4/C2,"") -> 0.23183391 | D6: =IFERROR(D4/D2,"") -> 0.31914894 | E6: =IFERROR(E4/E2,"") -> 1 | F6: =IFERROR(F4/F2,"") -> 0.84615385 | G6: =IFERROR(G4/G2,"") -> 0.62222222 | H6: =IFERROR(H4/H2,"") -> 0.84247375 | I6: =IFERROR(I4/I2,"") -> 0.8125 | J6: =IFERROR(J4/J2,"") -> 0.99479167 | ... L6: =IFERROR(L4/L2,"") -> 0.5
B7: Science-Ratio (Pages) | C7: =IFERROR(C5/C3,"") -> 0.40102758 | D7: =IFERROR(D5/D3,"") -> 0.47491039 | E7: =IFERROR(E5/E3,"") -> 1 | F7: =IFERROR(F5/F3,"") -> 0.84881587 | G7: =IFERROR(G5/G3,"") -> 0.69078014 | H7: =IFERROR(H5/H3,"") -> 0.90455412 | I7: =IFERROR(I5/I3,"") -> 0.85714286 | J7: =IFERROR(J5/J3,"") -> 0.99777518 | ... L7: =IFERROR(L5/L3,"") -> 0.390625
A8: Provenance,Articles (All) | B8: Local | C8: =COUNTIF('1. OP'!O2:O10002, "*Local*") -> 180 | D8: =COUNTIF('2. JSEL'!O2:O48, "*Local*") -> 28 | E8: =COUNTIF('3. PSM'!O2:O206, "*Local*") -> 28 | F8: =COUNTIF('4. SSP'!O2:O495, "*Local*") -> 262 | G8: =COUNTIF('5. JSACI'!O2:O46, "*Local*") -> 31 | H8: =COUNTIF('6. AIN'!O2:O858, "*Local*") -> 303 | I8: =COUNTIF('7. MS'!O2:O9999, "*Local*") -> 4 | J8: =COUNTIF('8. DS'!O2:O10006, "*Local*") -> 132 | K8: =COUNTIF('9. RMF'!O2:O10124, "*Local*") -> 452 | L8: =COUNTIF('10. PCU'!O2:O10001, "*Local*") -> 2
B9: Reuse (Translation) | C9: =COUNTIF('1. OP'!O2:O10002, "*Reuse (Translation)*") -> 59 | D9: =COUNTIF('2. JSEL'!O2:O48, "*Reuse (Translation)*") -> 13 | E9: =COUNTIF('3. PSM'!O2:O206, "*Reuse (Translation)*") -> 128 | F9: =COUNTIF('4. SSP'!O2:O495, "*Reuse (Translation)*") -> 173 | G9: =COUNTIF('5. JSACI'!O2:O46, "*Reuse (Translation)*") -> 6 | H9: =COUNTIF('6. AIN'!O2:O858, "*Reuse (Translation)*") -> 449 | I9: =COUNTIF('7. MS'!O2:O9999, "*Reuse (Translation)*") -> 10 | J9: =COUNTIF('8. DS'!O2:O10006, "*Reuse (Translation)*") -> 134 | K9: =COUNTIF('9. RMF'!O2:O10124, "*Reuse (Translation)*") -> 132 | L9: =COUNTIF('10. PCU'!O2:O10001, "*Reuse (Translation)*") -> 4
B10: Reuse (Reprint) | C10: =COUNTIF('1. OP'!O2:O10002, "*Reuse (Reprint)*") -> 34 | D10: =COUNTIF('2. JSEL'!O2:O48, "*Reuse (Reprint)*") -> 1 | E10: =COUNTIF('3. PSM'!O2:O206, "*Reuse (Reprint)*") -> 0 | F10: =COUNTIF('4. SSP'!O2:O495, "*Reuse (Reprint)*") -> 1 | G10: =COUNTIF('5. JSACI'!O2:O46, "*Reuse (Reprint)*") -> 1 | H10: =COUNTIF('6. AIN'!O2:O858, "*Reuse (Reprint)*") -> 50 | I10: =COUNTIF('7. MS'!O2:O9999, "*Reuse (Reprint)*") -> 0 | J10: =COUNTIF('8. DS'!O2:O10006, "*Reuse (Reprint)*") -> 18 | K10: =COUNTIF('9. RMF'!O2:O10124, "*Reuse (Reprint)*") -> 39 | L10: =COUNTIF('10. PCU'!O2:O10001, "*Reuse (Reprint)*") -> 1
B11: Adaptation | C11: =COUNTIF('1. OP'!O2:O10002, "*Adaptation*") -> 5 | D11: =COUNTIF('2. JSEL'!O2:O48, "*Adaptation*") -> 5 | E11: =COUNTIF('3. PSM'!O2:O206, "*Adaptation*") -> 49 | F11: =COUNTIF('4. SSP'!O2:O495, "*Adaptation*") -> 56 | G11: =COUNTIF('5. JSACI'!O2:O46, "*Adaptation*") -> 6 | H11: =COUNTIF('6. AIN'!O2:O858, "*Adaptation*") -> 53 | I11: =COUNTIF('7. MS'!O2:O9999, "*Adaptation*") -> 2 | J11: =COUNTIF('8. DS'!O2:O10006, "*Adaptation*") -> 98 | K11: =COUNTIF('9. RMF'!O2:O10124, "*Adaptation*") -> 76 | L11: =COUNTIF('10. PCU'!O2:O10001, "*Adaptation*") -> 1
B12: ESA (Total) | C12: =SUM(C9:C11) -> 98 | D12: =SUM(D9:D11) -> 19 | E12: =SUM(E9:E11) -> 177 | F12: =SUM(F9:F11) -> 230 | G12: =SUM(G9:G11) -> 13 | H12: =SUM(H9:H11) -> 552 | I12: =SUM(I9:I11) -> 12 | J12: =SUM(J9:J11) -> 250 | ... L12: =SUM(L9:L11) -> 6
B13: Trans.-Ratio | C13: =IFERROR(C9/C2,"") -> 0.20415225 | D13: =IFERROR(D9/D2,"") -> 0.27659574 | E13: =IFERROR(E9/E2,"") -> 0.62439024 | F13: =IFERROR(F9/F2,"") -> 0.35020243 | G13: =IFERROR(G9/G2,"") -> 0.13333333 | H13: =IFERROR(H9/H2,"") -> 0.52392065 | I13: =IFERROR(I9/I2,"") -> 0.625 | J13: =IFERROR(J9/J2,"") -> 0.34895833 | ... L13: =IFERROR(L9/L2,"") -> 0.5
B14: Reprint-Ratio | C14: =IFERROR(C10/C2,"") -> 0.11764706 | D14: =IFERROR(D10/D2,"") -> 0.021276596 | E14: =IFERROR(E10/E2,"") -> 0 | F14: =IFERROR(F10/F2,"") -> 0.0020242915 | G14: =IFERROR(G10/G2,"") -> 0.022222222 | H14: =IFERROR(H10/H2,"") -> 0.058343057 | I14: =IFERROR(I10/I2,"") -> 0 | J14: =IFERROR(J10/J2,"") -> 0.046875 | ... L14: =IFERROR(L10/L2,"") -> 0.125
B15: ESA-Ratio | C15: =IFERROR(C12/C2,"") -> 0.33910035 | D15: =IFERROR(D12/D2,"") -> 0.40425532 | E15: =IFERROR(E12/E2,"") -> 0.86341463 | F15: =IFERROR(F12/F2,"") -> 0.46558704 | G15: =IFERROR(G12/G2,"") -> 0.28888889 | H15: =IFERROR(H12/H2,"") -> 0.64410735 | I15: =IFERROR(I12/I2,"") -> 0.75 | J15: =IFERROR(J12/J2,"") -> 0.65104167 | ... L15: =IFERROR(L12/L2,"") -> 0.75
A16: Provenance, Articles (Scientific) | B16: Local | C16: =COUNTIFS('1. OP'!O2:O10002,"*Local*",'1. OP'!R2:R10002,"TRUE") -> 47 | D16: =COUNTIFS('2. JSEL'!O2:O48,"*Local*",'2. JSEL'!R2:R48,"TRUE") -> 4 | E16: =COUNTIFS('3. PSM'!O2:O206,"*Local*",'3. PSM'!R2:R206,"TRUE") -> 28 | F16: =COUNTIFS('4. SSP'!O2:O495,"*Local*",'4. SSP'!R2:R495,"TRUE") -> 186 | G16: =COUNTIFS('5. JSACI'!O2:O46,"*Local*",'5. JSACI'!R2:R46,"TRUE") -> 15 | H16: =COUNTIFS('6. AIN'!O2:O858,"*Local*",'6. AIN'!R2:R858,"TRUE") -> 169 | I16: =COUNTIFS('7. MS'!O2:O9999,"*Local*",'7. MS'!R2:R9999,"TRUE") -> 1 | J16: =COUNTIFS('8. DS'!O2:O10006,"*Local*",'8. DS'!R2:R10006,"TRUE") -> 130 | K16: =COUNTIFS('9. RMF'!O2:O10124,"*Local*",'9. RMF'!R2:R10124,"TRUE") -> 306 | L16: =COUNTIFS('10. PCU'!O2:O10001,"*Local*",'10. PCU'!R2:R10001,"TRUE") -> 0
B17: Reuse (Translation) | C17: =COUNTIFS('1. OP'!O2:O10002,"*Reuse (Translation)*",'1. OP'!R2:R10002,"TRUE") -> 3 | D17: =COUNTIFS('2. JSEL'!O2:O48,"*Reuse (Translation)*",'2. JSEL'!R2:R48,"TRUE") -> 7 | E17: =COUNTIFS('3. PSM'!O2:O206,"*Reuse (Translation)*",'3. PSM'!R2:R206,"TRUE") -> 128 | F17: =COUNTIFS('4. SSP'!O2:O495,"*Reuse (Translation)*",'4. SSP'!R2:R495,"TRUE") -> 173 | G17: =COUNTIFS('5. JSACI'!O2:O46,"*Reuse (Translation)*",'5. JSACI'!R2:R46,"TRUE") -> 5 | H17: =COUNTIFS('6. AIN'!O2:O858,"*Reuse (Translation)*",'6. AIN'!R2:R858,"TRUE") -> 448 | I17: =COUNTIFS('7. MS'!O2:O9999,"*Reuse (Translation)*",'7. MS'!R2:R9999,"TRUE") -> 10 | J17: =COUNTIFS('8. DS'!O2:O10006,"*Reuse (Translation)*",'8. DS'!R2:R10006,"TRUE") -> 134 | K17: =COUNTIFS('9. RMF'!O2:O10124,"*Reuse (Translation)*",'9. RMF'!R2:R10124,"TRUE") -> 132 | L17: =COUNTIFS('10. PCU'!O2:O10001,"*Reuse (Translation)*",'10. PCU'!R2:R10001,"TRUE") -> 3
B18: Reuse (Reprint) | C18: =COUNTIFS('1. OP'!O2:O10002,"*Reuse (Reprint)*",'1. OP'!R2:R10002,"TRUE") -> 7 | D18: =COUNTIFS('2. JSEL'!O2:O48,"*Reuse (Reprint)*",'2. JSEL'!R2:R48,"TRUE") -> 0 | E18: =COUNTIFS('3. PSM'!O2:O206,"*Reuse (Reprint)*",'3. PSM'!R2:R206,"TRUE") -> 0 | F18: =COUNTIFS('4. SSP'!O2:O495,"*Reuse (Reprint)*",'4. SSP'!R2:R495,"TRUE") -> 1 | G18: =COUNTIFS('5. JSACI'!O2:O46,"*Reuse (Reprint)*",'5. JSACI'!R2:R46,"TRUE") -> 1 | H18: =COUNTIFS('6. AIN'!O2:O858,"*Reuse (Reprint)*",'6. AIN'!R2:R858,"TRUE") -> 50 | I18: =COUNTIFS('7. MS'!O2:O9999,"*Reuse (Reprint)*",'7. MS'!R2:R9999,"TRUE") -> 0 | J18: =COUNTIFS('8. DS'!O2:O10006,"*Reuse (Reprint)*",'8. DS'!R2:R10006,"TRUE") -> 18 | K18: =COUNTIFS('9. RMF'!O2:O10124,"*Reuse (Reprint)*",'9. RMF'!R2:R10124,"TRUE") -> 39 | L18: =COUNTIFS('10. PCU'!O2:O10001,"*Reuse (Reprint)*",'10. PCU'!R2:R10001,"TRUE") -> 0
B19: Adaptation | C19: =COUNTIFS('1. OP'!O2:O10002,"*Adaptation*",'1. OP'!R2:R10002,"TRUE") -> 4 | D19: =COUNTIFS('2. JSEL'!O2:O48,"*Adaptation*",'2. JSEL'!R2:R48,"TRUE") -> 4 | E19: =COUNTIFS('3. PSM'!O2:O206,"*Adaptation*",'3. PSM'!R2:R206,"TRUE") -> 49 | F19: =COUNTIFS('4. SSP'!O2:O495,"*Adaptation*",'4. SSP'!R2:R495,"TRUE") -> 56 | G19: =COUNTIFS('5. JSACI'!O2:O46,"*Adaptation*",'5. JSACI'!R2:R46,"TRUE") -> 6 | H19: =COUNTIFS('6. AIN'!O2:O858,"*Adaptation*",'6. AIN'!R2:R858,"TRUE") -> 53 | I19: =COUNTIFS('7. MS'!O2:O9999,"*Adaptation*",'7. MS'!R2:R9999,"TRUE") -> 2 | J19: =COUNTIFS('8. DS'!O2:O10006,"*Adaptation*",'8. DS'!R2:R10006,"TRUE") -> 98 | K19: =COUNTIFS('9. RMF'!O2:O10124,"*Adaptation*",'9. RMF'!R2:R10124,"TRUE") -> 76 | L19: =COUNTIFS('10. PCU'!O2:O10001,"*Adaptation*",'10. PCU'!R2:R10001,"TRUE") -> 1
B20: ESA (Total) | C20: =SUM(C17:C19) -> 14 | D20: =SUM(D17:D19) -> 11 | E20: =SUM(E17:E19) -> 177 | F20: =SUM(F17:F19) -> 230 | G20: =SUM(G17:G19) -> 12 | H20: =SUM(H17:H19) -> 551 | I20: =SUM(I17:I19) -> 12 | J20: =SUM(J17:J19) -> 250 | ... L20: =SUM(L17:L19) -> 4
B21: Trans.-Ratio | C21: =IFERROR(C17/C4,"") -> 0.044776119 | D21: =IFERROR(D17/D4,"") -> 0.46666667 | E21: =IFERROR(E17/E4,"") -> 0.62439024 | F21: =IFERROR(F17/F4,"") -> 0.4138756 | G21: =IFERROR(G17/G4,"") -> 0.17857143 | H21: =IFERROR(H17/H4,"") -> 0.62049861 | I21: =IFERROR(I17/I4,"") -> 0.76923077 | J21: =IFERROR(J17/J4,"") -> 0.35078534 | ... L21: =IFERROR(L17/L4,"") -> 0.75
B22: Reprint-Ratio | C22: =IFERROR(C18/C4,"") -> 0.10447761 | D22: =IFERROR(D18/D4,"") -> 0 | E22: =IFERROR(E18/E4,"") -> 0 | F22: =IFERROR(F18/F4,"") -> 0.0023923445 | G22: =IFERROR(G18/G4,"") -> 0.035714286 | H22: =IFERROR(H18/H4,"") -> 0.069252078 | I22: =IFERROR(I18/I4,"") -> 0 | J22: =IFERROR(J18/J4,"") -> 0.047120419 | ... L22: =IFERROR(L18/L4,"") -> 0
B23: ESA-Ratio | C23: =IFERROR(C20/C4,"") -> 0.20895522 | D23: =IFERROR(D20/D4,"") -> 0.73333333 | E23: =IFERROR(E20/E4,"") -> 0.86341463 | F23: =IFERROR(F20/F4,"") -> 0.55023923 | G23: =IFERROR(G20/G4,"") -> 0.42857143 | H23: =IFERROR(H20/H4,"") -> 0.76315789 | I23: =IFERROR(I20/I4,"") -> 0.92307692 | J23: =IFERROR(J20/J4,"") -> 0.65445026 | ... L23: =IFERROR(L20/L4,"") -> 1
A24: Provenance, Pages (Scientific) | B24: Local | C24: =SUMIFS('1. OP'!$H:$H,'1. OP'!$R:$R,"TRUE",'1. OP'!$O:$O,"Local") -> 514 | D24: =SUMIFS('2. JSEL'!$H:$H,'2. JSEL'!$R:$R,"TRUE",'2. JSEL'!$O:$O,"Local") -> 39 | E24: =SUMIFS('3. PSM'!$H:$H,'3. PSM'!$R:$R,"TRUE",'3. PSM'!$O:$O,"Local") -> 161.33333 | F24: =SUMIFS('4. SSP'!$H:$H,'4. SSP'!$R:$R,"TRUE",'4. SSP'!$O:$O,"Local") -> 298.98333 | G24: =SUMIFS('5. JSACI'!$H:$H,'5. JSACI'!$R:$R,"TRUE",'5. JSACI'!$O:$O,"Local") -> 105.5 | H24: =SUMIFS('6. AIN'!$H:$H,'6. AIN'!$R:$R,"TRUE",'6. AIN'!$O:$O,"Local") -> 945 | I24: =SUMIFS('7. MS'!$H:$H,'7. MS'!$R:$R,"TRUE",'7. MS'!$O:$O,"Local") -> 0.5 | J24: =SUMIFS('8. DS'!$H:$H,'8. DS'!$R:$R,"TRUE",'8. DS'!$O:$O,"Local") -> 160.0619 | K24: =SUMIFS('9. RMF'!$H:$H,'9. RMF'!$R:$R,"TRUE",'9. RMF'!$O:$O,"Local") -> 1744.4167 | L24: =SUMIFS('10. PCU'!$H:$H,'10. PCU'!$R:$R,"TRUE",'10. PCU'!$O:$O,"Local") -> 0
B25: Reuse (Translation) | C25: =SUMIFS('1. OP'!$H:$H,'1. OP'!$R:$R,"TRUE",'1. OP'!$O:$O,"Reuse (Translation)") -> 24.5 | D25: =SUMIFS('2. JSEL'!$H:$H,'2. JSEL'!$R:$R,"TRUE",'2. JSEL'!$O:$O,"Reuse (Translation)") -> 50 | E25: =SUMIFS('3. PSM'!$H:$H,'3. PSM'!$R:$R,"TRUE",'3. PSM'!$O:$O,"Reuse (Translation)") -> 775.33333 | F25: =SUMIFS('4. SSP'!$H:$H,'4. SSP'!$R:$R,"TRUE",'4. SSP'!$O:$O,"Reuse (Translation)") -> 137.82381 | G25: =SUMIFS('5. JSACI'!$H:$H,'5. JSACI'!$R:$R,"TRUE",'5. JSACI'!$O:$O,"Reuse (Translation)") -> 25.833333 | H25: =SUMIFS('6. AIN'!$H:$H,'6. AIN'!$R:$R,"TRUE",'6. AIN'!$O:$O,"Reuse (Translation)") -> 1714.0833 | I25: =SUMIFS('7. MS'!$H:$H,'7. MS'!$R:$R,"TRUE",'7. MS'!$O:$O,"Reuse (Translation)") -> 9.6666667 | J25: =SUMIFS('8. DS'!$H:$H,'8. DS'!$R:$R,"TRUE",'8. DS'!$O:$O,"Reuse (Translation)") -> 153.16429 | K25: =SUMIFS('9. RMF'!$H:$H,'9. RMF'!$R:$R,"TRUE",'9. RMF'!$O:$O,"Reuse (Translation)") -> 500.03333 | L25: =SUMIFS('10. PCU'!$H:$H,'10. PCU'!$R:$R,"TRUE",'10. PCU'!$O:$O,"Reuse (Translation)") -> 1.25
B26: Reuse (Reprint) | C26: =SUMIFS('1. OP'!$H:$H,'1. OP'!$R:$R,"TRUE",'1. OP'!$O:$O,"Reuse (Reprint)") -> 76 | D26: =SUMIFS('2. JSEL'!$H:$H,'2. JSEL'!$R:$R,"TRUE",'2. JSEL'!$O:$O,"Reuse (Reprint)") -> 0 | E26: =SUMIFS('3. PSM'!$H:$H,'3. PSM'!$R:$R,"TRUE",'3. PSM'!$O:$O,"Reuse (Reprint)") -> 0 | F26: =SUMIFS('4. SSP'!$H:$H,'4. SSP'!$R:$R,"TRUE",'4. SSP'!$O:$O,"Reuse (Reprint)") -> 3.5 | G26: =SUMIFS('5. JSACI'!$H:$H,'5. JSACI'!$R:$R,"TRUE",'5. JSACI'!$O:$O,"Reuse (Reprint)") -> 6 | H26: =SUMIFS('6. AIN'!$H:$H,'6. AIN'!$R:$R,"TRUE",'6. AIN'!$O:$O,"Reuse (Reprint)") -> 216.75 | I26: =SUMIFS('7. MS'!$H:$H,'7. MS'!$R:$R,"TRUE",'7. MS'!$O:$O,"Reuse (Reprint)") -> 0 | J26: =SUMIFS('8. DS'!$H:$H,'8. DS'!$R:$R,"TRUE",'8. DS'!$O:$O,"Reuse (Reprint)") -> 50.166667 | K26: =SUMIFS('9. RMF'!$H:$H,'9. RMF'!$R:$R,"TRUE",'9. RMF'!$O:$O,"Reuse (Reprint)") -> 119.61667 | L26: =SUMIFS('10. PCU'!$H:$H,'10. PCU'!$R:$R,"TRUE",'10. PCU'!$O:$O,"Reuse (Reprint)") -> 0
B27: Adaptation | C27: =SUMIFS('1. OP'!$H:$H,'1. OP'!$R:$R,"TRUE",'1. OP'!$O:$O,"Adaptation") -> 42 | D27: =SUMIFS('2. JSEL'!$H:$H,'2. JSEL'!$R:$R,"TRUE",'2. JSEL'!$O:$O,"Adaptation") -> 43.5 | E27: =SUMIFS('3. PSM'!$H:$H,'3. PSM'!$R:$R,"TRUE",'3. PSM'!$O:$O,"Adaptation") -> 126.33333 | F27: =SUMIFS('4. SSP'!$H:$H,'4. SSP'!$R:$R,"TRUE",'4. SSP'!$O:$O,"Adaptation") -> 36.909524 | G27: =SUMIFS('5. JSACI'!$H:$H,'5. JSACI'!$R:$R,"TRUE",'5. JSACI'!$O:$O,"Adaptation") -> 23.5 | H27: =SUMIFS('6. AIN'!$H:$H,'6. AIN'!$R:$R,"TRUE",'6. AIN'!$O:$O,"Adaptation") -> 121.5 | I27: =SUMIFS('7. MS'!$H:$H,'7. MS'!$R:$R,"TRUE",'7. MS'!$O:$O,"Adaptation") -> 1.8333333 | J27: =SUMIFS('8. DS'!$H:$H,'8. DS'!$R:$R,"TRUE",'8. DS'!$O:$O,"Adaptation") -> 59.907143 | K27: =SUMIFS('9. RMF'!$H:$H,'9. RMF'!$R:$R,"TRUE",'9. RMF'!$O:$O,"Adaptation") -> 96.1 | L27: =SUMIFS('10. PCU'!$H:$H,'10. PCU'!$R:$R,"TRUE",'10. PCU'!$O:$O,"Adaptation") -> 5
B28: ESA (Total) | C28: =SUM(C25:C27) -> 142.5 | D28: =SUM(D25:D27) -> 93.5 | E28: =SUM(E25:E27) -> 901.66667 | F28: =SUM(F25:F27) -> 178.23333 | G28: =SUM(G25:G27) -> 55.333333 | H28: =SUM(H25:H27) -> 2052.3333 | I28: =SUM(I25:I27) -> 11.5 | J28: =SUM(J25:J27) -> 263.2381 | ... L28: =SUM(L25:L27) -> 6.25
B29: Trans.-Ratio | C29: =IFERROR(C25/C5,"") -> 0.033041133 | D29: =IFERROR(D25/D5,"") -> 0.37735849 | E29: =IFERROR(E25/E5,"") -> 0.72938225 | F29: =IFERROR(F25/F5,"") -> 0.28840472 | G29: =IFERROR(G25/G5,"") -> 0.15913758 | H29: =IFERROR(H25/H5,"") -> 0.57025229 | I29: =IFERROR(I25/I5,"") -> 0.80555556 | J29: =IFERROR(J25/J5,"") -> 0.35949838 | ... L29: =IFERROR(L25/L5,"") -> 0.2
B30: Reprint-Ratio | C30: =IFERROR(C26/C5,"") -> 0.10249494 | D30: =IFERROR(D26/D5,"") -> 0 | E30: =IFERROR(E26/E5,"") -> 0 | F30: =IFERROR(F26/F5,"") -> 0.0073239633 | G30: =IFERROR(G26/G5,"") -> 0.036960986 | H30: =IFERROR(H26/H5,"") -> 0.072109787 | I30: =IFERROR(I26/I5,"") -> 0 | J30: =IFERROR(J26/J5,"") -> 0.11774831 | ... L30: =IFERROR(L26/L5,"") -> 0
B31: ESA-Ratio | C31: =IFERROR(C28/C5,"") -> 0.19217802 | D31: =IFERROR(D28/D5,"") -> 0.70566038 | E31: =IFERROR(E28/E5,"") -> 0.84822828 | F31: =IFERROR(F28/F5,"") -> 0.37296411 | G31: =IFERROR(G28/G5,"") -> 0.34086242 | H31: =IFERROR(H28/H5,"") -> 0.68278348 | I31: =IFERROR(I28/I5,"") -> 0.95833333 | J31: =IFERROR(J28/J5,"") -> 0.61785728 | ... L31: =IFERROR(L28/L5,"") -> 1

Sheet 1. OP
A1: File | B1: ID | C1: Date | D1: Vol. | E1: Issue | F1: Start | G1: End | H1: Size | I1: Section | J1: Title | K1: AuthorhipAttribution | L1: SourceAttribution | M1: ProximateSourceIdentification | N1: Reference | O1: TextualProvenanceClassification | P1: ProximateSourceLocation | Q1: Notes | R1: Science
A2: OP1813s1v1 | B2: OP1813.1.1.1-1 | C2: 01/1813 | D2: 1 | E2: 1 | F2: 3 | G2: 8 | H2: {=_xlfn.LET(_xlpm.s,IFERROR(--F2,""),_xlpm.e,IFERROR(--G2,""),IF(OR(_xlpm.s="",_xlpm.e="",_xlpm.e<_xlpm.s),"",_xlfn.LET(_xlpm.p,_xlfn.SEQUENCE(_xlpm.e-_xlpm.s+1,1,_xlpm.s,1),SUM(1/COUNTIFS($D:$D,D2,$E:$E,E2,$F:$F,"<>N/A",$G:$G,"<>N/A",$F:$F,"<="&_xlpm.p,$G:$G,">="&_xlpm.p)))))} -> 6 | I2: N/A | J2: Introducção. | K2: N/A | L2: N/A | M2: N/A | N2: N/A | O2: Local | P2: Brazil | R2: FALSE
A3: OP1813s1v1 | B3: OP1813.1.1.1-2 | C3: 01/1813 | D3: 1 | E3: 1 | F3: 9 | G3: 10 | H3: {=_xlfn.LET(_xlpm.s,IFERROR(--F3,""),_xlpm.e,IFERROR(--G3,""),IF(OR(_xlpm.s="",_xlpm.e="",_xlpm.e<_xlpm.s),"",_xlfn.LET(_xlpm.p,_xlfn.SEQUENCE(_xlpm.e-_xlpm.s+1,1,_xlpm.s,1),SUM(1/COUNTIFS($D:$D,D3,$E:$E,E3,$F:$F,"<>N/A",$G:$G,"<>N/A",$F:$F,"<="&_xlpm.p,$G:$G,">="&_xlpm.p)))))} -> 1.5 | I3: Artes | J3: Memoria sobre o emprego do assucar combinado com a polvora, extrahida do Repertoio das Artes, Manufacturas, e Agricultura | K3: N/A | L3: Repertory of Arts, &cc. n.º 125 | M3: RAMA1812s2v21 | N3: “Specification of the Patent granted to Frederick Albert Winsor...” The Repertory of Arts, Manufactures, and Agriculture (London) 2nd ser., 21, no. 125 (1812): 261–262. | O3: Adaptation | P3: United Kingdom | R3: TRUE
A4: OP1813s1v1 | B4: OP1813.1.1.1-3 | C4: 01/1813 | D4: 1 | E4: 1 | F4: 10 | G4: 21 | H4: {=_xlfn.LET(_xlpm.s,IFERROR(--F4,""),_xlpm.e,IFERROR(--G4,""),IF(OR(_xlpm.s="",_xlpm.e="",_xlpm.e<_xlpm.s),"",_xlfn.LET(_xlpm.p,_xlfn.SEQUENCE(_xlpm.e-_xlpm.s+1,1,_xlpm.s,1),SUM(1/COUNTIFS($D:$D,D4,$E:$E,E4,$F:$F,"<>N/A",$G:$G,"<>N/A",$F:$F,"<="&_xlpm.p,$G:$G,">="&_xlpm.p)))))} -> 11.5 | I4: Artes | J4: Novo methodo para refinar assucar por Luiz Honoré Henry German Constant, premiado a 27 de fevereiro de 1812 | K4: N/A | L4: N/A | M4: RAMA1812s2v21 | N4: "Specification of the Patent granted to Louis Honoré Henry Germain Constant, of Blandford-street, Portman-square, in the Parish of Saint Mary-le-bone, and County of Middlesex; for a Method of refining Sugars. Dated February 27, 1812." The Repertory of Arts, Manufactures, and Agriculture (London) 2nd ser., 21, no. 124 (1812): 207–216. | O4: Reuse (Translation) | P4: United Kingdom | R4: TRUE
A5: OP1813s1v1 | B5: OP1813.1.1.1-4 | C5: 01/1813 | D5: 1 | E5: 1 | F5: 22 | G5: 34 | H5: {=_xlfn.LET(_xlpm.s,IFERROR(--F5,""),_xlpm.e,IFERROR(--G5,""),IF(OR(_xlpm.s="",_xlpm.e="",_xlpm.e<_xlpm.s),"",_xlfn.LET(_xlpm.p,_xlfn.SEQUENCE(_xlpm.e-_xlpm.s+1,1,_xlpm.s,1),SUM(1/COUNTIFS($D:$D,D5,$E:$E,E5,$F:$F,"<>N/A",$G:$G,"<>N/A",$F:$F,"<="&_xlpm.p,$G:$G,">="&_xlpm.p)))))} -> 12.5 | I5: Agricultura | J5: Memoria sobre a cultura dos algodoeiros, por Manoel Arruda da Câmara, Doutor em Medicina pela Universidade de Montpellier, da Academia das Sciencias da mesma Cidade, Correspondente da Sociedade de Agricultura de Pariz, e da Academia Real das Sciencias de Lisboa, e Naturalista empregado no Serviço de S. M. Fidelissima na Capitania de Pernambuco. Anno de 1797. Capítulo I. Da antiguidade do uso do algodão, e da vantagem, que tem resultado a Portugal, e a Pernambuco, da sua cultura. | K5: Manuel Arruda da Câmara | L5: Memoria sobre a cultura dos algodoeiros | M5: N/A | N5: Câmara, Manuel Arruda da. Memoria sobre a cultura dos algodoeiros, e sobre o methodo de o escolher, e ensacar, etc.: em que se propoem alguns planos novos, para o seu melhoramento. Lisbon: Na Officina da Casa Litteraria do Arco do Cego, 1799. [4], 80, [3] p., [6] fold. plates. | O5: Reuse (Reprint) | P5: Portugal | R5: TRUE
A6: OP1813s1v1 | B6: OP1813.1.1.1-5 | C6: 01/1813 | D6: 1 | E6: 1 | F6: 34 | G6: 49 | H6: {=_xlfn.LET(_xlpm.s,IFERROR(--F6,""),_xlpm.e,IFERROR(--G6,""),IF(OR(_xlpm.s="",_xlpm.e="",_xlpm.e<_xlpm.s),"",_xlfn.LET(_xlpm.p,_xlfn.SEQUENCE(_xlpm.e-_xlpm.s+1,1,_xlpm.s,1),SUM(1/COUNTIFS($D:$D,D6,$E:$E,E6,$F:$F,"<>N/A",$G:$G,"<>N/A",$F:$F,"<="&_xlpm.p,$G:$G,">="&_xlpm.p)))))} -> 15 | I6: Agricultura | J6: Memoria sobre a plantação e fabrico do Urucú, por B* | K6: Domingos Borges de Barros | L6: N/A | M6: N/A | N6: Leblond, Jean-Baptiste. “Mémoire sur la préparation du rocou et sur la culture du rocouyer.” In Mémoires de la Société d’agriculture de Paris, tome 6, 65–133. Paris, 1804. | O6: Adaptation | P6: France | Q6: The article is a adaption of Jean-Baptiste Leblond’s Mémoire sur la culture du roucouyer à la Guyane française (Mémoires de la Société d’agriculture du département de la Seine, 1804) with additional material from contemporary French chemical literature (particularly Vauquelin and Chaptal). | R6: TRUE
A7: OP1813s1v1 | B7: OP1813.1.1.1-6 | C7: 01/1813 | D7: 1 | E7: 1 | F7: 49 | G7: 57 | H7: {=_xlfn.LET(_xlpm.s,IFERROR(--F7,""),_xlpm.e,IFERROR(--G7,""),IF(OR(_xlpm.s="",_xlpm.e="",_xlpm.e<_xlpm.s),"",_xlfn.LET(_xlpm.p,_xlfn.SEQUENCE(_xlpm.e-_xlpm.s+1,1,_xlpm.s,1),SUM(1/COUNTIFS($D:$D,D7,$E:$E,E7,$F:$F,"<>N/A",$G:$G,"<>N/A",$F:$F,"<="&_xlpm.p,$G:$G,">="&_xlpm.p)))))} -> 8.5 | I7: Hidrografia | J7: Methodo, que se seguiu no trabalho Hydrographico da Planta do Porto do Rio de Janeiro, levantada por Ordem do Serenissimo Senhor Infante Almirante General, em o anno de 1810. | K7: D.J.B. | L7: N/A | M7: N/A | N7: N/A | O7: Local | P7: Brazil | R7: TRUE
A8: OP1813s1v1 | B8: OP1813.1.1.1-7 | C8: 01/1813 | D8: 1 | E8: 1 | F8: 58 | G8: 59 | H8: {=_xlfn.LET(_xlpm.s,IFERROR(--F8,""),_xlpm.e,IFERROR(--G8,""),IF(OR(_xlpm.s="",_xlpm.e="",_xlpm.e<_xlpm.s),"",_xlfn.LET(_xlpm.p,_xlfn.SEQUENCE(_xlpm.e-_xlpm.s+1,1,_xlpm.s,1),SUM(1/COUNTIFS($D:$D,D8,$E:$E,E8,$F:$F,"<>N/A",$G:$G,"<>N/A",$F:$F,"<="&_xlpm.p,$G:$G,">="&_xlpm.p)))))} -> 2 | I8: Medicina | J8: No anno de 1798 se propoz por Acordo da Camara desta Cidade a varios Medicos, hum Programma que tinha por objecto os quesitos seguintes. | K8: N/A | L8: N/A | M8: N/A | N8: N/A | O8: Local | P8: Brazil | R8: TRUE
A9: OP1813s1v1 | B9: OP1813.1.1.1-8 | C9: 01/1813 | D9: 1 | E9: 1 | F9: 60 | G9: 67 | H9: {=_xlfn.LET(_xlpm.s,IFERROR(--F9,""),_xlpm.e,IFERROR(--G9,""),IF(OR(_xlpm.s="",_xlpm.e="",_xlpm.e<_xlpm.s),"",_xlfn.LET(_xlpm.p,_xlfn.SEQUENCE(_xlpm.e-_xlpm.s+1,1,_xlpm.s,1),SUM(1/COUNTIFS($D:$D,D9,$E:$E,E9,$F:$F,"<>N/A",$G:$G,"<>N/A",$F:$F,"<="&_xlpm.p,$G:$G,">="&_xlpm.p)))))} -> 8 | I9: Medicina | J9: Resposta, que deu o Doutor Manoel Joaquim Marreiros, aos quesitos precedentes. | K9: Manoel Joaquim Marreiros | L9: N/A | M9: N/A | N9: N/A | O9: Local | P9: Brazil | R9: TRUE
A10: OP1813s1v1 | B10: OP1813.1.1.1-9 | C10: 01/1813 | D10: 1 | E10: 1 | F10: 68 | G10: 73 | H10: {=_xlfn.LET(_xlpm.s,IFERROR(--F10,""),_xlpm.e,IFERROR(--G10,""),IF(OR(_xlpm.s="",_xlpm.e="",_xlpm.e<_xlpm.s),"",_xlfn.LET(_xlpm.p,_xlfn.SEQUENCE(_xlpm.e-_xlpm.s+1,1,_xlpm.s,1),SUM(1/COUNTIFS($D:$D,D10,$E:$E,E10,$F:$F,"<>N/A",$G:$G,"<>N/A",$F:$F,"<="&_xlpm.p,$G:$G,">="&_xlpm.p)))))} -> 6 | I10: Litteratura | J10: Ode. A’ partida de S. A. R. o Principe Regente Nosso Senhor, de Portugal para o Brazil, feita em Paris aos 5 (a) de Janeiro de 1808 ; e recitada em prezença dos Bons Portuguezes alli existentes. | K10: Domingos Borges de Barros | L10: N/A | M10: N/A | N10: N/A | O10: Local | P10: Brazil | R10: FALSE
A11: OP1813s1v1 | B11: OP1813.1.1.1-10 | C11: 01/1813 | D11: 1 | E11: 1 | F11: 74 | G11: 75 | H11: {=_xlfn.LET(_xlpm.s,IFERROR(--F11,""),_xlpm.e,IFERROR(--G11,""),IF(OR(_xlpm.s="",_xlpm.e="",_xlpm.e<_xlpm.s),"",_xlfn.LET(_xlpm.p,_xlfn.SEQUENCE(_xlpm.e-_xlpm.s+1,1,_xlpm.s,1),SUM(1/COUNTIFS($D:$D,D11,$E:$E,E11,$F:$F,"<>N/A",$G:$G,"<>N/A",$F:$F,"<="&_xlpm.p,$G:$G,">="&_xlpm.p)))))} -> 2 | I11: Litteratura | J11: Do Dezembargador Antonio Ribeiro dos Santos a Francisco de Borja Garção Stockler. Ode. | K11: Antonio Ribeiro dos Santos | L11: N/A | M11: N/A | N11: N/A | O11: Local | P11: Brazil | R11: FALSE
A12: OP1813s1v1 | B12: OP1813.1.1.1-11 | C12: 01/1813 | D12: 1 | E12: 1 | F12: 76 | G12: 78 | H12: {=_xlfn.LET(_xlpm.s,IFERROR(--F12,""),_xlpm.e,IFERROR(--G12,""),IF(OR(_xlpm.s="",_xlpm.e="",_xlpm.e<_xlpm.s),"",_xlfn.LET(_xlpm.p,_xlfn.SEQUENCE(_xlpm.e-_xlpm.s+1,1,_xlpm.s,1),SUM(1/COUNTIFS($D:$D,D12,$E:$E,E12,$F:$F,"<>N/A",$G:$G,"<>N/A",$F:$F,"<="&_xlpm.p,$G:$G,">="&_xlpm.p)))))} -> 3 | I12: Litteratura | J12: Ode. Ao Illustrissimo Antonio Ribeiro dos Santos, em resposta á antecêdente, por Francisco de Borja Garção Stockler. | K12: Francisco de Borja Garção Stockler | L12: N/A | M12: N/A | N12: N/A | O12: Local | P12: Brazil | R12: FALSE
A13: OP1813s1v1 | B13: OP1813.1.1.1-12 | C13: 01/1813 | D13: 1 | E13: 1 | F13: 79 | G13: 87 | H13: {=_xlfn.LET(_xlpm.s,IFERROR(--F13,""),_xlpm.e,IFERROR(--G13,""),IF(OR(_xlpm.s="",_xlpm.e="",_xlpm.e<_xlpm.s),"",_xlfn.LET(_xlpm.p,_xlfn.SEQUENCE(_xlpm.e-_xlpm.s+1,1,_xlpm.s,1),SUM(1/COUNTIFS($D:$D,D13,$E:$E,E13,$F:$F,"<>N/A",$G:$G,"<>N/A",$F:$F,"<="&_xlpm.p,$G:$G,">="&_xlpm.p)))))} -> 9 | I13: Litteratura | J13: Ode Pindarica. Ao grande Affonso de Albuquerque, Governador da India. Por Antonio Diniz da Cruz. | K13: Antonio Diniz da Cruz | L13: N/A | M13: N/A | N13: Cruz e Silva, António Diniz da. Poesias de Antonio Diniz da Cruz e Silva na Arcadia de Lisboa Elpino Nonacriense. Tom. III: Que contém as Poesias Líricas. Lisbon: Typografia Lacerdina, 1812. | O13: Reuse (Reprint) | P13: Portugal | R13: FALSE
A14: OP1813s1v1 | B14: OP1813.1.1.1-13 | C14: 01/1813 | D14: 1 | E14: 1 | F14: 88 | G14: 90 | H14: {=_xlfn.LET(_xlpm.s,IFERROR(--F14,""),_xlpm.e,IFERROR(--G14,""),IF(OR(_xlpm.s="",_xlpm.e="",_xlpm.e<_xlpm.s),"",_xlfn.LET(_xlpm.p,_xlfn.SEQUENCE(_xlpm.e-_xlpm.s+1,1,_xlpm.s,1),SUM(1/COUNTIFS($D:$D,D14,$E:$E,E14,$F:$F,"<>N/A",$G:$G,"<>N/A",$F:$F,"<="&_xlpm.p,$G:$G,">="&_xlpm.p)))))} -> 3 | I14: Litteratura | J14: Lira Inedita de T. A. Gonzaga, Author da celebre Marilia de Dirceo. | K14: T. A. Gonzaga | L14: N/A | M14: N/A | N14: N/A | O14: Local | P14: Brazil | R14: FALSE
A15: OP1813s1v1 | B15: OP1813.1.1.1-14 | C15: 01/1813 | D15: 1 | E15: 1 | F15: 91 | G15: 93 | H15: {=_xlfn.LET(_xlpm.s,IFERROR(--F15,""),_xlpm.e,IFERROR(--G15,""),IF(OR(_xlpm.s="",_xlpm.e="",_xlpm.e<_xlpm.s),"",_xlfn.LET(_xlpm.p,_xlfn.SEQUENCE(_xlpm.e-_xlpm.s+1,1,_xlpm.s,1),SUM(1/COUNTIFS($D:$D,D15,$E:$E,E15,$F:$F,"<>N/A",$G:$G,"<>N/A",$F:$F,"<="&_xlpm.p,$G:$G,">="&_xlpm.p)))))} -> 2.5 | I15: Litteratura | J15: Maximas, Pensamentos, e Reflexoẽs Moraes por hum Brazileiro. | K15: Mariano Pereira da Fonseca | L15: N/A | M15: N/A | N15: N/A | O15: Local | P15: Brazil | R15: FALSE
A16: OP1813s1v1 | B16: OP1813.1.1.1-15 | C16: 01/1813 | D16: 1 | E16: 1 | F16: 93 | G16: 95 | H16: {=_xlfn.LET(_xlpm.s,IFERROR(--F16,""),_xlpm.e,IFERROR(--G16,""),IF(OR(_xlpm.s="",_xlpm.e="",_xlpm.e<_xlpm.s),"",_xlfn.LET(_xlpm.p,_xlfn.SEQUENCE(_xlpm.e-_xlpm.s+1,1,_xlpm.s,1),SUM(1/COUNTIFS($D:$D,D16,$E:$E,E16,$F:$F,"<>N/A",$G:$G,"<>N/A",$F:$F,"<="&_xlpm.p,$G:$G,">="&_xlpm.p)))))} -> 2 | I16: Litteratura | J16: ["Em huma questão..."] Questão grammatical sobre as Syllabas por S.P.F. | K16: S.P.F. | L16: N/A | M16: N/A | N16: N/A | O16: Local | P16: Brazil | R16: FALSE
A17: OP1813s1v1 | B17: OP1813.1.1.1-16 | C17: 01/1813 | D17: 1 | E17: 1 | F17: 95 | G17: 96 | H17: {=_xlfn.LET(_xlpm.s,IFERROR(--F17,""),_xlpm.e,IFERROR(--G17,""),IF(OR(_xlpm.s="",_xlpm.e="",_xlpm.e<_xlpm.s),"",_xlfn.LET(_xlpm.p,_xlfn.SEQUENCE(_xlpm.e-_xlpm.s+1,1,_xlpm.s,1),SUM(1/COUNTIFS($D:$D,D17,$E:$E,E17,$F:$F,"<>N/A",$G:$G,"<>N/A",$F:$F,"<="&_xlpm.p,$G:$G,">="&_xlpm.p)))))} -> 1.5 | I17: Litteratura | J17: Correspondencia. | K17: S.r…; D.B.B. | L17: N/A | M17: N/A | N17: N/A | O17: Local | P17: Brazil | R17: FALSE
A18: OP1813s1v1 | B18: OP1813.1.1.1-17 | C18: 01/1813 | D18: 1 | E18: 1 | F18: 97 | G18: 100 | H18: {=_xlfn.LET(_xlpm.s,IFERROR(--F18,""),_xlpm.e,IFERROR(--G18,""),IF(OR(_xlpm.s="",_xlpm.e="",_xlpm.e<_xlpm.s),"",_xlfn.LET(_xlpm.p,_xlfn.SEQUENCE(_xlpm.e-_xlpm.s+1,1,_xlpm.s,1),SUM(1/COUNTIFS($D:$D,D18,$E:$E,E18,$F:$F,"<>N/A",$G:$G,"<>N/A",$F:$F,"<="&_xlpm.p,$G:$G,">="&_xlpm.p)))))} -> 4 | I18: História | J18: Extracto da viagem, que fez ao sertão de Benguella no anno de 1785 por ordem do Governador e Capitão General do Reino de Angola, o Bacharel Joaquim José da Silva, enviado à aquelle Reino como Naturalista, e depois Secretario do Governo de Loanda para Benguella. | K18: Joaquim José da Silva | L18: N/A | M18: N/A | N18: Silva, Joaquim José da. Letter to Júlio Mattiazzi. Benguela, 24 May 1787. Manuscript, CN/S-22. Arquivo Histórico do Museu Bocage, Museu Nacional de História Natural e da Ciência (MUHNAC/ULisboa), Lisbon; Silva, Joaquim José da. Letter to Júlio Mattiazzi. Luanda, 9 July 1787. Manuscript, CN/S-23. Arquivo Histórico do Museu Bocage, Museu Nacional de História Natural e da Ciência (MUHNAC/ULisboa), Lisbon. | O18: N/A | P18: Portugal | R18: FALSE
A19: OP1813s1v1 | B19: OP1813.1.1.1-18 | C19: 01/1813 | D19: 1 | E19: 1 | F19: 101 | G19: 107 | H19: {=_xlfn.LET(_xlpm.s,IFERROR(--F19,""),_xlpm.e,IFERROR(--G19,""),IF(OR(_xlpm.s="",_xlpm.e="",_xlpm.e<_xlpm.s),"",_xlfn.LET(_xlpm.p,_xlfn.SEQUENCE(_xlpm.e-_xlpm.s+1,1,_xlpm.s,1),SUM(1/COUNTIFS($D:$D,D19,$E:$E,E19,$F:$F,"<>N/A",$G:$G,"<>N/A",$F:$F,"<="&_xlpm.p,$G:$G,">="&_xlpm.p)))))} -> 7 | I19: Política | J19: Calculo sobre a perda de dinheiro do Reino, offerecido ao Senhor Rei D. JOAM QUINTO, de eterna gloria, por Alexandre de Gusmão, Seu Secretario do Estado, Fielmente copiado do seu original authographo. | K19: Alexandre de Gusmão | L19: N/A | M19: N/A | N19: N/A | O19: Reuse (Reprint) | P19: Portugal | Q19: Seventeenth-century Portuguese state paper reproduced for Rio readers. | R19: FALSE
A20: OP1813s1v1 | B20: OP1813.1.1.1-19 | C20: 01/1813 | D20: 1 | E20: 1 | F20: 108 | G20: 109 | H20: {=_xlfn.LET(_xlpm.s,IFERROR(--F20,""),_xlpm.e,IFERROR(--G20,""),IF(OR(_xlpm.s="",_xlpm.e="",_xlpm.e<_xlpm.s),"",_xlfn.LET(_xlpm.p,_xlfn.SEQUENCE(_xlpm.e-_xlpm.s+1,1,_xlpm.s,1),SUM(1/COUNTIFS($D:$D,D20,$E:$E,E20,$F:$F,"<>N/A",$G:$G,"<>N/A",$F:$F,"<="&_xlpm.p,$G:$G,">="&_xlpm.p)))))} -> 2 | I20: Política | J20: Tratado de paz entre S. M. o Rei da Suecia, e S. M. o Rei do Reino Unido da Gran Bretanha e Irlãnda. | K20: Barão de Engerstrom, Barão de Wotlersdet, Edward Thornton | L20: N/A | M20: N/A | N20: N/A | O20: Reuse (Translation) | P20: Portugal | Q20: Diplomatic text carried via Portuguese official prints. | R20: FALSE
A21: OP1813s1v1 | B21: OP1813.1.1.1-20 | C21: 01/1813 | D21: 1 | E21: 1 | F21: 110 | G21: 111 | H21: {=_xlfn.LET(_xlpm.s,IFERROR(--F21,""),_xlpm.e,IFERROR(--G21,""),IF(OR(_xlpm.s="",_xlpm.e="",_xlpm.e<_xlpm.s),"",_xlfn.LET(_xlpm.p,_xlfn.SEQUENCE(_xlpm.e-_xlpm.s+1,1,_xlpm.s,1),SUM(1/COUNTIFS($D:$D,D21,$E:$E,E21,$F:$F,"<>N/A",$G:$G,"<>N/A",$F:$F,"<="&_xlpm.p,$G:$G,">="&_xlpm.p)))))} -> 2 | I21: Política | J21: Tratado de Amizade, União e Alliança entre a Hespanha e a Russia. | K21: Francisco de Zea Bermudes, Conde Nicolao de Romanzoff | L21: N/A | M21: N/A | N21: N/A | O21: Reuse (Translation) | P21: Russia | Q21: Same treaty-reprint pattern as above. | R21: FALSE
A22: OP1813s1v1 | B22: OP1813.1.1.1-21 | C22: 01/1813 | D22: 1 | E22: 1 | F22: 112 | G22: 121 | H22: {=_xlfn.LET(_xlpm.s,IFERROR(--F22,""),_xlpm.e,IFERROR(--G22,""),IF(OR(_xlpm.s="",_xlpm.e="",_xlpm.e<_xlpm.s),"",_xlfn.LET(_xlpm.p,_xlfn.SEQUENCE(_xlpm.e-_xlpm.s+1,1,_xlpm.s,1),SUM(1/COUNTIFS($D:$D,D22,$E:$E,E22,$F:$F,"<>N/A",$G:$G,"<>N/A",$F:$F,"<="&_xlpm.p,$G:$G,">="&_xlpm.p)))))} -> 9.5 | I22: Política | J22: Estado politico da Europa. | K22: N/A | L22: N/A | M22: N/A | N22: N/A | O22: Local | P22: Brazil | R22: FALSE
A23: OP1813s1v1 | B23: OP1813.1.1.1-22 | C23: 01/1813 | D23: 1 | E23: 1 | F23: 121 | G23: 122 | H23: {=_xlfn.LET(_xlpm.s,IFERROR(--F23,""),_xlpm.e,IFERROR(--G23,""),IF(OR(_xlpm.s="",_xlpm.e="",_xlpm.e<_xlpm.s),"",_xlfn.LET(_xlpm.p,_xlfn.SEQUENCE(_xlpm.e-_xlpm.s+1,1,_xlpm.s,1),SUM(1/COUNTIFS($D:$D,D23,$E:$E,E23,$F:$F,"<>N/A",$G:$G,"<>N/A",$F:$F,"<="&_xlpm.p,$G:$G,">="&_xlpm.p)))))} -> 1 | I23: Política | J23: Obras publicadas no Rio de Janeiro no presente mez de Janeiro. | K23: N/A | L23: N/A | M23: N/A | N23: N/A | O23: Local | P23: Brazil | R23: FALSE
A24: OP1813s1v1 | B24: OP1813.1.1.1-23 | C24: 01/1813 | D24: 1 | E24: 1 | F24: 122 | G24: 125 | H24: {=_xlfn.LET(_xlpm.s,IFERROR(--F24,""),_xlpm.e,IFERROR(--G24,""),IF(OR(_xlpm.s="",_xlpm.e="",_xlpm.e<_xlpm.s),"",_xlfn.LET(_xlpm.p,_xlfn.SEQUENCE(_xlpm.e-_xlpm.s+1,1,_xlpm.s,1),SUM(1/COUNTIFS($D:$D,D24,$E:$E,E24,$F:$F,"<>N/A",$G:$G,"<>N/A",$F:$F,"<="&_xlpm.p,$G:$G,">="&_xlpm.p)))))} -> 3.5 | I24: Comércio | J24: Mappa das Embarcações Portuguezas que entrarão em Gibraltar no anno de 1811, e suas importações, e exportações, extrahido de Documentos Officiaes. | K24: N/A | L24: N/A | M24: N/A | N24: N/A | O24: Reuse (Reprint) | P24: Portugal | Q24: Consular/official Portuguese data reproduced for the journal. | R24: FALSE
